[DEBUG] 2021-09-22 20:24:26,784 | /home/attiq/frappe-bench/apps/frappe/frappe/utils/scheduler.py:
Site: erp.sample
Access denied for site erp.sample
[DEBUG] 2021-09-22 20:24:26,790 | /home/attiq/frappe-bench/apps/frappe/frappe/utils/scheduler.py:
Site: foo.bar
Access denied for site foo.bar
[DEBUG] 2021-09-22 20:24:26,837 | /home/attiq/frappe-bench/apps/frappe/frappe/utils/scheduler.py:
Site: gourmet.nerp
Queued events for site gourmet.nerp
[DEBUG] 2021-09-22 20:24:26,842 | /home/attiq/frappe-bench/apps/frappe/frappe/utils/scheduler.py:
Site: gourmet.nrp
Access denied for site gourmet.nrp
[DEBUG] 2021-09-22 20:24:26,845 | /home/attiq/frappe-bench/apps/frappe/frappe/utils/scheduler.py:
Site: local.nerp
Access denied for site local.nerp
[DEBUG] 2021-09-22 20:25:26,920 | /home/attiq/frappe-bench/apps/frappe/frappe/utils/scheduler.py:
Site: erp.sample
Access denied for site erp.sample
[DEBUG] 2021-09-22 20:25:26,925 | /home/attiq/frappe-bench/apps/frappe/frappe/utils/scheduler.py:
Site: foo.bar
Access denied for site foo.bar
[DEBUG] 2021-09-22 20:25:26,972 | /home/attiq/frappe-bench/apps/frappe/frappe/utils/scheduler.py:
Site: gourmet.nerp
Queued events for site gourmet.nerp
[DEBUG] 2021-09-22 20:25:26,977 | /home/attiq/frappe-bench/apps/frappe/frappe/utils/scheduler.py:
Site: gourmet.nrp
Access denied for site gourmet.nrp
[DEBUG] 2021-09-22 20:25:26,981 | /home/attiq/frappe-bench/apps/frappe/frappe/utils/scheduler.py:
Site: local.nerp
Access denied for site local.nerp
[ERROR] 2021-09-22 22:13:25,188 | /home/attiq/frappe-bench/apps/frappe/frappe/utils/scheduler.py:
Site: erp.sample
Exception in Enqueue Events for Site erp.sample
Traceback (most recent call last):
  File "/home/attiq/frappe-bench/env/lib/python3.6/site-packages/pymysql/connections.py", line 583, in connect
    **kwargs)
  File "/usr/lib/python3.6/socket.py", line 724, in create_connection
    raise err
  File "/usr/lib/python3.6/socket.py", line 713, in create_connection
    sock.connect(sa)
OSError: [Errno 101] Network is unreachable

During handling of the above exception, another exception occurred:

Traceback (most recent call last):
  File "/home/attiq/frappe-bench/apps/frappe/frappe/utils/scheduler.py", line 81, in enqueue_events_for_site
    if is_scheduler_inactive():
  File "/home/attiq/frappe-bench/apps/frappe/frappe/utils/scheduler.py", line 228, in is_scheduler_inactive
    if is_scheduler_disabled():
  File "/home/attiq/frappe-bench/apps/frappe/frappe/utils/scheduler.py", line 237, in is_scheduler_disabled
    return not frappe.utils.cint(frappe.db.get_single_value("System Settings", "enable_scheduler"))
  File "/home/attiq/frappe-bench/apps/frappe/frappe/database/database.py", line 553, in get_single_value
    `tabSingles` where `doctype`=%s and `field`=%s""", (doctype, fieldname))
  File "/home/attiq/frappe-bench/apps/frappe/frappe/database/database.py", line 122, in sql
    self.connect()
  File "/home/attiq/frappe-bench/apps/frappe/frappe/database/database.py", line 75, in connect
    self._conn = self.get_connection()
  File "/home/attiq/frappe-bench/apps/frappe/frappe/database/mariadb/database.py", line 90, in get_connection
    local_infile = frappe.conf.local_infile)
  File "/home/attiq/frappe-bench/env/lib/python3.6/site-packages/pymysql/__init__.py", line 94, in Connect
    return Connection(*args, **kwargs)
  File "/home/attiq/frappe-bench/env/lib/python3.6/site-packages/pymysql/connections.py", line 325, in __init__
    self.connect()
  File "/home/attiq/frappe-bench/env/lib/python3.6/site-packages/pymysql/connections.py", line 630, in connect
    raise exc
pymysql.err.OperationalError: (2003, "Can't connect to MySQL server on '192.168.2.219' ([Errno 101] Network is unreachable)")

[ERROR] 2021-09-22 22:13:25,189 | /home/attiq/frappe-bench/apps/frappe/frappe/utils/scheduler.py:
Site: foo.bar
Exception in Enqueue Events for Site foo.bar
Traceback (most recent call last):
  File "/home/attiq/frappe-bench/env/lib/python3.6/site-packages/pymysql/connections.py", line 583, in connect
    **kwargs)
  File "/usr/lib/python3.6/socket.py", line 724, in create_connection
    raise err
  File "/usr/lib/python3.6/socket.py", line 713, in create_connection
    sock.connect(sa)
OSError: [Errno 101] Network is unreachable

During handling of the above exception, another exception occurred:

Traceback (most recent call last):
  File "/home/attiq/frappe-bench/apps/frappe/frappe/utils/scheduler.py", line 81, in enqueue_events_for_site
    if is_scheduler_inactive():
  File "/home/attiq/frappe-bench/apps/frappe/frappe/utils/scheduler.py", line 228, in is_scheduler_inactive
    if is_scheduler_disabled():
  File "/home/attiq/frappe-bench/apps/frappe/frappe/utils/scheduler.py", line 237, in is_scheduler_disabled
    return not frappe.utils.cint(frappe.db.get_single_value("System Settings", "enable_scheduler"))
  File "/home/attiq/frappe-bench/apps/frappe/frappe/database/database.py", line 553, in get_single_value
    `tabSingles` where `doctype`=%s and `field`=%s""", (doctype, fieldname))
  File "/home/attiq/frappe-bench/apps/frappe/frappe/database/database.py", line 122, in sql
    self.connect()
  File "/home/attiq/frappe-bench/apps/frappe/frappe/database/database.py", line 75, in connect
    self._conn = self.get_connection()
  File "/home/attiq/frappe-bench/apps/frappe/frappe/database/mariadb/database.py", line 90, in get_connection
    local_infile = frappe.conf.local_infile)
  File "/home/attiq/frappe-bench/env/lib/python3.6/site-packages/pymysql/__init__.py", line 94, in Connect
    return Connection(*args, **kwargs)
  File "/home/attiq/frappe-bench/env/lib/python3.6/site-packages/pymysql/connections.py", line 325, in __init__
    self.connect()
  File "/home/attiq/frappe-bench/env/lib/python3.6/site-packages/pymysql/connections.py", line 630, in connect
    raise exc
pymysql.err.OperationalError: (2003, "Can't connect to MySQL server on '192.168.2.219' ([Errno 101] Network is unreachable)")

[ERROR] 2021-09-22 22:13:25,190 | /home/attiq/frappe-bench/apps/frappe/frappe/utils/scheduler.py:
Site: gourmet.nerp
Exception in Enqueue Events for Site gourmet.nerp
Traceback (most recent call last):
  File "/home/attiq/frappe-bench/env/lib/python3.6/site-packages/pymysql/connections.py", line 583, in connect
    **kwargs)
  File "/usr/lib/python3.6/socket.py", line 724, in create_connection
    raise err
  File "/usr/lib/python3.6/socket.py", line 713, in create_connection
    sock.connect(sa)
OSError: [Errno 101] Network is unreachable

During handling of the above exception, another exception occurred:

Traceback (most recent call last):
  File "/home/attiq/frappe-bench/apps/frappe/frappe/utils/scheduler.py", line 81, in enqueue_events_for_site
    if is_scheduler_inactive():
  File "/home/attiq/frappe-bench/apps/frappe/frappe/utils/scheduler.py", line 228, in is_scheduler_inactive
    if is_scheduler_disabled():
  File "/home/attiq/frappe-bench/apps/frappe/frappe/utils/scheduler.py", line 237, in is_scheduler_disabled
    return not frappe.utils.cint(frappe.db.get_single_value("System Settings", "enable_scheduler"))
  File "/home/attiq/frappe-bench/apps/frappe/frappe/database/database.py", line 553, in get_single_value
    `tabSingles` where `doctype`=%s and `field`=%s""", (doctype, fieldname))
  File "/home/attiq/frappe-bench/apps/frappe/frappe/database/database.py", line 122, in sql
    self.connect()
  File "/home/attiq/frappe-bench/apps/frappe/frappe/database/database.py", line 75, in connect
    self._conn = self.get_connection()
  File "/home/attiq/frappe-bench/apps/frappe/frappe/database/mariadb/database.py", line 90, in get_connection
    local_infile = frappe.conf.local_infile)
  File "/home/attiq/frappe-bench/env/lib/python3.6/site-packages/pymysql/__init__.py", line 94, in Connect
    return Connection(*args, **kwargs)
  File "/home/attiq/frappe-bench/env/lib/python3.6/site-packages/pymysql/connections.py", line 325, in __init__
    self.connect()
  File "/home/attiq/frappe-bench/env/lib/python3.6/site-packages/pymysql/connections.py", line 630, in connect
    raise exc
pymysql.err.OperationalError: (2003, "Can't connect to MySQL server on '192.168.2.79' ([Errno 101] Network is unreachable)")

[ERROR] 2021-09-22 22:13:25,191 | /home/attiq/frappe-bench/apps/frappe/frappe/utils/scheduler.py:
Site: gourmet.nrp
Exception in Enqueue Events for Site gourmet.nrp
Traceback (most recent call last):
  File "/home/attiq/frappe-bench/env/lib/python3.6/site-packages/pymysql/connections.py", line 583, in connect
    **kwargs)
  File "/usr/lib/python3.6/socket.py", line 724, in create_connection
    raise err
  File "/usr/lib/python3.6/socket.py", line 713, in create_connection
    sock.connect(sa)
OSError: [Errno 101] Network is unreachable

During handling of the above exception, another exception occurred:

Traceback (most recent call last):
  File "/home/attiq/frappe-bench/apps/frappe/frappe/utils/scheduler.py", line 81, in enqueue_events_for_site
    if is_scheduler_inactive():
  File "/home/attiq/frappe-bench/apps/frappe/frappe/utils/scheduler.py", line 228, in is_scheduler_inactive
    if is_scheduler_disabled():
  File "/home/attiq/frappe-bench/apps/frappe/frappe/utils/scheduler.py", line 237, in is_scheduler_disabled
    return not frappe.utils.cint(frappe.db.get_single_value("System Settings", "enable_scheduler"))
  File "/home/attiq/frappe-bench/apps/frappe/frappe/database/database.py", line 553, in get_single_value
    `tabSingles` where `doctype`=%s and `field`=%s""", (doctype, fieldname))
  File "/home/attiq/frappe-bench/apps/frappe/frappe/database/database.py", line 122, in sql
    self.connect()
  File "/home/attiq/frappe-bench/apps/frappe/frappe/database/database.py", line 75, in connect
    self._conn = self.get_connection()
  File "/home/attiq/frappe-bench/apps/frappe/frappe/database/mariadb/database.py", line 90, in get_connection
    local_infile = frappe.conf.local_infile)
  File "/home/attiq/frappe-bench/env/lib/python3.6/site-packages/pymysql/__init__.py", line 94, in Connect
    return Connection(*args, **kwargs)
  File "/home/attiq/frappe-bench/env/lib/python3.6/site-packages/pymysql/connections.py", line 325, in __init__
    self.connect()
  File "/home/attiq/frappe-bench/env/lib/python3.6/site-packages/pymysql/connections.py", line 630, in connect
    raise exc
pymysql.err.OperationalError: (2003, "Can't connect to MySQL server on '192.168.2.219' ([Errno 101] Network is unreachable)")

[ERROR] 2021-09-22 22:13:25,192 | /home/attiq/frappe-bench/apps/frappe/frappe/utils/scheduler.py:
Site: local.nerp
Exception in Enqueue Events for Site local.nerp
Traceback (most recent call last):
  File "/home/attiq/frappe-bench/env/lib/python3.6/site-packages/pymysql/connections.py", line 583, in connect
    **kwargs)
  File "/usr/lib/python3.6/socket.py", line 724, in create_connection
    raise err
  File "/usr/lib/python3.6/socket.py", line 713, in create_connection
    sock.connect(sa)
OSError: [Errno 101] Network is unreachable

During handling of the above exception, another exception occurred:

Traceback (most recent call last):
  File "/home/attiq/frappe-bench/apps/frappe/frappe/utils/scheduler.py", line 81, in enqueue_events_for_site
    if is_scheduler_inactive():
  File "/home/attiq/frappe-bench/apps/frappe/frappe/utils/scheduler.py", line 228, in is_scheduler_inactive
    if is_scheduler_disabled():
  File "/home/attiq/frappe-bench/apps/frappe/frappe/utils/scheduler.py", line 237, in is_scheduler_disabled
    return not frappe.utils.cint(frappe.db.get_single_value("System Settings", "enable_scheduler"))
  File "/home/attiq/frappe-bench/apps/frappe/frappe/database/database.py", line 553, in get_single_value
    `tabSingles` where `doctype`=%s and `field`=%s""", (doctype, fieldname))
  File "/home/attiq/frappe-bench/apps/frappe/frappe/database/database.py", line 122, in sql
    self.connect()
  File "/home/attiq/frappe-bench/apps/frappe/frappe/database/database.py", line 75, in connect
    self._conn = self.get_connection()
  File "/home/attiq/frappe-bench/apps/frappe/frappe/database/mariadb/database.py", line 90, in get_connection
    local_infile = frappe.conf.local_infile)
  File "/home/attiq/frappe-bench/env/lib/python3.6/site-packages/pymysql/__init__.py", line 94, in Connect
    return Connection(*args, **kwargs)
  File "/home/attiq/frappe-bench/env/lib/python3.6/site-packages/pymysql/connections.py", line 325, in __init__
    self.connect()
  File "/home/attiq/frappe-bench/env/lib/python3.6/site-packages/pymysql/connections.py", line 630, in connect
    raise exc
pymysql.err.OperationalError: (2003, "Can't connect to MySQL server on '192.168.2.219' ([Errno 101] Network is unreachable)")

[ERROR] 2021-09-22 22:14:35,269 | /home/attiq/frappe-bench/apps/frappe/frappe/utils/scheduler.py:
Site: erp.sample
Exception in Enqueue Events for Site erp.sample
Traceback (most recent call last):
  File "/home/attiq/frappe-bench/env/lib/python3.6/site-packages/pymysql/connections.py", line 583, in connect
    **kwargs)
  File "/usr/lib/python3.6/socket.py", line 724, in create_connection
    raise err
  File "/usr/lib/python3.6/socket.py", line 713, in create_connection
    sock.connect(sa)
socket.timeout: timed out

During handling of the above exception, another exception occurred:

Traceback (most recent call last):
  File "/home/attiq/frappe-bench/apps/frappe/frappe/utils/scheduler.py", line 81, in enqueue_events_for_site
    if is_scheduler_inactive():
  File "/home/attiq/frappe-bench/apps/frappe/frappe/utils/scheduler.py", line 228, in is_scheduler_inactive
    if is_scheduler_disabled():
  File "/home/attiq/frappe-bench/apps/frappe/frappe/utils/scheduler.py", line 237, in is_scheduler_disabled
    return not frappe.utils.cint(frappe.db.get_single_value("System Settings", "enable_scheduler"))
  File "/home/attiq/frappe-bench/apps/frappe/frappe/database/database.py", line 553, in get_single_value
    `tabSingles` where `doctype`=%s and `field`=%s""", (doctype, fieldname))
  File "/home/attiq/frappe-bench/apps/frappe/frappe/database/database.py", line 122, in sql
    self.connect()
  File "/home/attiq/frappe-bench/apps/frappe/frappe/database/database.py", line 75, in connect
    self._conn = self.get_connection()
  File "/home/attiq/frappe-bench/apps/frappe/frappe/database/mariadb/database.py", line 90, in get_connection
    local_infile = frappe.conf.local_infile)
  File "/home/attiq/frappe-bench/env/lib/python3.6/site-packages/pymysql/__init__.py", line 94, in Connect
    return Connection(*args, **kwargs)
  File "/home/attiq/frappe-bench/env/lib/python3.6/site-packages/pymysql/connections.py", line 325, in __init__
    self.connect()
  File "/home/attiq/frappe-bench/env/lib/python3.6/site-packages/pymysql/connections.py", line 630, in connect
    raise exc
pymysql.err.OperationalError: (2003, "Can't connect to MySQL server on '192.168.2.219' (timed out)")

[ERROR] 2021-09-22 22:14:45,282 | /home/attiq/frappe-bench/apps/frappe/frappe/utils/scheduler.py:
Site: foo.bar
Exception in Enqueue Events for Site foo.bar
Traceback (most recent call last):
  File "/home/attiq/frappe-bench/env/lib/python3.6/site-packages/pymysql/connections.py", line 583, in connect
    **kwargs)
  File "/usr/lib/python3.6/socket.py", line 724, in create_connection
    raise err
  File "/usr/lib/python3.6/socket.py", line 713, in create_connection
    sock.connect(sa)
socket.timeout: timed out

During handling of the above exception, another exception occurred:

Traceback (most recent call last):
  File "/home/attiq/frappe-bench/apps/frappe/frappe/utils/scheduler.py", line 81, in enqueue_events_for_site
    if is_scheduler_inactive():
  File "/home/attiq/frappe-bench/apps/frappe/frappe/utils/scheduler.py", line 228, in is_scheduler_inactive
    if is_scheduler_disabled():
  File "/home/attiq/frappe-bench/apps/frappe/frappe/utils/scheduler.py", line 237, in is_scheduler_disabled
    return not frappe.utils.cint(frappe.db.get_single_value("System Settings", "enable_scheduler"))
  File "/home/attiq/frappe-bench/apps/frappe/frappe/database/database.py", line 553, in get_single_value
    `tabSingles` where `doctype`=%s and `field`=%s""", (doctype, fieldname))
  File "/home/attiq/frappe-bench/apps/frappe/frappe/database/database.py", line 122, in sql
    self.connect()
  File "/home/attiq/frappe-bench/apps/frappe/frappe/database/database.py", line 75, in connect
    self._conn = self.get_connection()
  File "/home/attiq/frappe-bench/apps/frappe/frappe/database/mariadb/database.py", line 90, in get_connection
    local_infile = frappe.conf.local_infile)
  File "/home/attiq/frappe-bench/env/lib/python3.6/site-packages/pymysql/__init__.py", line 94, in Connect
    return Connection(*args, **kwargs)
  File "/home/attiq/frappe-bench/env/lib/python3.6/site-packages/pymysql/connections.py", line 325, in __init__
    self.connect()
  File "/home/attiq/frappe-bench/env/lib/python3.6/site-packages/pymysql/connections.py", line 630, in connect
    raise exc
pymysql.err.OperationalError: (2003, "Can't connect to MySQL server on '192.168.2.219' (timed out)")

[ERROR] 2021-09-22 22:14:55,291 | /home/attiq/frappe-bench/apps/frappe/frappe/utils/scheduler.py:
Site: gourmet.nerp
Exception in Enqueue Events for Site gourmet.nerp
Traceback (most recent call last):
  File "/home/attiq/frappe-bench/env/lib/python3.6/site-packages/pymysql/connections.py", line 583, in connect
    **kwargs)
  File "/usr/lib/python3.6/socket.py", line 724, in create_connection
    raise err
  File "/usr/lib/python3.6/socket.py", line 713, in create_connection
    sock.connect(sa)
socket.timeout: timed out

During handling of the above exception, another exception occurred:

Traceback (most recent call last):
  File "/home/attiq/frappe-bench/apps/frappe/frappe/utils/scheduler.py", line 81, in enqueue_events_for_site
    if is_scheduler_inactive():
  File "/home/attiq/frappe-bench/apps/frappe/frappe/utils/scheduler.py", line 228, in is_scheduler_inactive
    if is_scheduler_disabled():
  File "/home/attiq/frappe-bench/apps/frappe/frappe/utils/scheduler.py", line 237, in is_scheduler_disabled
    return not frappe.utils.cint(frappe.db.get_single_value("System Settings", "enable_scheduler"))
  File "/home/attiq/frappe-bench/apps/frappe/frappe/database/database.py", line 553, in get_single_value
    `tabSingles` where `doctype`=%s and `field`=%s""", (doctype, fieldname))
  File "/home/attiq/frappe-bench/apps/frappe/frappe/database/database.py", line 122, in sql
    self.connect()
  File "/home/attiq/frappe-bench/apps/frappe/frappe/database/database.py", line 75, in connect
    self._conn = self.get_connection()
  File "/home/attiq/frappe-bench/apps/frappe/frappe/database/mariadb/database.py", line 90, in get_connection
    local_infile = frappe.conf.local_infile)
  File "/home/attiq/frappe-bench/env/lib/python3.6/site-packages/pymysql/__init__.py", line 94, in Connect
    return Connection(*args, **kwargs)
  File "/home/attiq/frappe-bench/env/lib/python3.6/site-packages/pymysql/connections.py", line 325, in __init__
    self.connect()
  File "/home/attiq/frappe-bench/env/lib/python3.6/site-packages/pymysql/connections.py", line 630, in connect
    raise exc
pymysql.err.OperationalError: (2003, "Can't connect to MySQL server on '192.168.2.79' (timed out)")

[ERROR] 2021-09-22 22:15:05,302 | /home/attiq/frappe-bench/apps/frappe/frappe/utils/scheduler.py:
Site: gourmet.nrp
Exception in Enqueue Events for Site gourmet.nrp
Traceback (most recent call last):
  File "/home/attiq/frappe-bench/env/lib/python3.6/site-packages/pymysql/connections.py", line 583, in connect
    **kwargs)
  File "/usr/lib/python3.6/socket.py", line 724, in create_connection
    raise err
  File "/usr/lib/python3.6/socket.py", line 713, in create_connection
    sock.connect(sa)
socket.timeout: timed out

During handling of the above exception, another exception occurred:

Traceback (most recent call last):
  File "/home/attiq/frappe-bench/apps/frappe/frappe/utils/scheduler.py", line 81, in enqueue_events_for_site
    if is_scheduler_inactive():
  File "/home/attiq/frappe-bench/apps/frappe/frappe/utils/scheduler.py", line 228, in is_scheduler_inactive
    if is_scheduler_disabled():
  File "/home/attiq/frappe-bench/apps/frappe/frappe/utils/scheduler.py", line 237, in is_scheduler_disabled
    return not frappe.utils.cint(frappe.db.get_single_value("System Settings", "enable_scheduler"))
  File "/home/attiq/frappe-bench/apps/frappe/frappe/database/database.py", line 553, in get_single_value
    `tabSingles` where `doctype`=%s and `field`=%s""", (doctype, fieldname))
  File "/home/attiq/frappe-bench/apps/frappe/frappe/database/database.py", line 122, in sql
    self.connect()
  File "/home/attiq/frappe-bench/apps/frappe/frappe/database/database.py", line 75, in connect
    self._conn = self.get_connection()
  File "/home/attiq/frappe-bench/apps/frappe/frappe/database/mariadb/database.py", line 90, in get_connection
    local_infile = frappe.conf.local_infile)
  File "/home/attiq/frappe-bench/env/lib/python3.6/site-packages/pymysql/__init__.py", line 94, in Connect
    return Connection(*args, **kwargs)
  File "/home/attiq/frappe-bench/env/lib/python3.6/site-packages/pymysql/connections.py", line 325, in __init__
    self.connect()
  File "/home/attiq/frappe-bench/env/lib/python3.6/site-packages/pymysql/connections.py", line 630, in connect
    raise exc
pymysql.err.OperationalError: (2003, "Can't connect to MySQL server on '192.168.2.219' (timed out)")

[ERROR] 2021-09-22 22:15:15,318 | /home/attiq/frappe-bench/apps/frappe/frappe/utils/scheduler.py:
Site: local.nerp
Exception in Enqueue Events for Site local.nerp
Traceback (most recent call last):
  File "/home/attiq/frappe-bench/env/lib/python3.6/site-packages/pymysql/connections.py", line 583, in connect
    **kwargs)
  File "/usr/lib/python3.6/socket.py", line 724, in create_connection
    raise err
  File "/usr/lib/python3.6/socket.py", line 713, in create_connection
    sock.connect(sa)
socket.timeout: timed out

During handling of the above exception, another exception occurred:

Traceback (most recent call last):
  File "/home/attiq/frappe-bench/apps/frappe/frappe/utils/scheduler.py", line 81, in enqueue_events_for_site
    if is_scheduler_inactive():
  File "/home/attiq/frappe-bench/apps/frappe/frappe/utils/scheduler.py", line 228, in is_scheduler_inactive
    if is_scheduler_disabled():
  File "/home/attiq/frappe-bench/apps/frappe/frappe/utils/scheduler.py", line 237, in is_scheduler_disabled
    return not frappe.utils.cint(frappe.db.get_single_value("System Settings", "enable_scheduler"))
  File "/home/attiq/frappe-bench/apps/frappe/frappe/database/database.py", line 553, in get_single_value
    `tabSingles` where `doctype`=%s and `field`=%s""", (doctype, fieldname))
  File "/home/attiq/frappe-bench/apps/frappe/frappe/database/database.py", line 122, in sql
    self.connect()
  File "/home/attiq/frappe-bench/apps/frappe/frappe/database/database.py", line 75, in connect
    self._conn = self.get_connection()
  File "/home/attiq/frappe-bench/apps/frappe/frappe/database/mariadb/database.py", line 90, in get_connection
    local_infile = frappe.conf.local_infile)
  File "/home/attiq/frappe-bench/env/lib/python3.6/site-packages/pymysql/__init__.py", line 94, in Connect
    return Connection(*args, **kwargs)
  File "/home/attiq/frappe-bench/env/lib/python3.6/site-packages/pymysql/connections.py", line 325, in __init__
    self.connect()
  File "/home/attiq/frappe-bench/env/lib/python3.6/site-packages/pymysql/connections.py", line 630, in connect
    raise exc
pymysql.err.OperationalError: (2003, "Can't connect to MySQL server on '192.168.2.219' (timed out)")

[ERROR] 2021-09-22 22:16:25,393 | /home/attiq/frappe-bench/apps/frappe/frappe/utils/scheduler.py:
Site: erp.sample
Exception in Enqueue Events for Site erp.sample
Traceback (most recent call last):
  File "/home/attiq/frappe-bench/env/lib/python3.6/site-packages/pymysql/connections.py", line 583, in connect
    **kwargs)
  File "/usr/lib/python3.6/socket.py", line 724, in create_connection
    raise err
  File "/usr/lib/python3.6/socket.py", line 713, in create_connection
    sock.connect(sa)
socket.timeout: timed out

During handling of the above exception, another exception occurred:

Traceback (most recent call last):
  File "/home/attiq/frappe-bench/apps/frappe/frappe/utils/scheduler.py", line 81, in enqueue_events_for_site
    if is_scheduler_inactive():
  File "/home/attiq/frappe-bench/apps/frappe/frappe/utils/scheduler.py", line 228, in is_scheduler_inactive
    if is_scheduler_disabled():
  File "/home/attiq/frappe-bench/apps/frappe/frappe/utils/scheduler.py", line 237, in is_scheduler_disabled
    return not frappe.utils.cint(frappe.db.get_single_value("System Settings", "enable_scheduler"))
  File "/home/attiq/frappe-bench/apps/frappe/frappe/database/database.py", line 553, in get_single_value
    `tabSingles` where `doctype`=%s and `field`=%s""", (doctype, fieldname))
  File "/home/attiq/frappe-bench/apps/frappe/frappe/database/database.py", line 122, in sql
    self.connect()
  File "/home/attiq/frappe-bench/apps/frappe/frappe/database/database.py", line 75, in connect
    self._conn = self.get_connection()
  File "/home/attiq/frappe-bench/apps/frappe/frappe/database/mariadb/database.py", line 90, in get_connection
    local_infile = frappe.conf.local_infile)
  File "/home/attiq/frappe-bench/env/lib/python3.6/site-packages/pymysql/__init__.py", line 94, in Connect
    return Connection(*args, **kwargs)
  File "/home/attiq/frappe-bench/env/lib/python3.6/site-packages/pymysql/connections.py", line 325, in __init__
    self.connect()
  File "/home/attiq/frappe-bench/env/lib/python3.6/site-packages/pymysql/connections.py", line 630, in connect
    raise exc
pymysql.err.OperationalError: (2003, "Can't connect to MySQL server on '192.168.2.219' (timed out)")

[ERROR] 2021-09-22 22:16:35,406 | /home/attiq/frappe-bench/apps/frappe/frappe/utils/scheduler.py:
Site: foo.bar
Exception in Enqueue Events for Site foo.bar
Traceback (most recent call last):
  File "/home/attiq/frappe-bench/env/lib/python3.6/site-packages/pymysql/connections.py", line 583, in connect
    **kwargs)
  File "/usr/lib/python3.6/socket.py", line 724, in create_connection
    raise err
  File "/usr/lib/python3.6/socket.py", line 713, in create_connection
    sock.connect(sa)
socket.timeout: timed out

During handling of the above exception, another exception occurred:

Traceback (most recent call last):
  File "/home/attiq/frappe-bench/apps/frappe/frappe/utils/scheduler.py", line 81, in enqueue_events_for_site
    if is_scheduler_inactive():
  File "/home/attiq/frappe-bench/apps/frappe/frappe/utils/scheduler.py", line 228, in is_scheduler_inactive
    if is_scheduler_disabled():
  File "/home/attiq/frappe-bench/apps/frappe/frappe/utils/scheduler.py", line 237, in is_scheduler_disabled
    return not frappe.utils.cint(frappe.db.get_single_value("System Settings", "enable_scheduler"))
  File "/home/attiq/frappe-bench/apps/frappe/frappe/database/database.py", line 553, in get_single_value
    `tabSingles` where `doctype`=%s and `field`=%s""", (doctype, fieldname))
  File "/home/attiq/frappe-bench/apps/frappe/frappe/database/database.py", line 122, in sql
    self.connect()
  File "/home/attiq/frappe-bench/apps/frappe/frappe/database/database.py", line 75, in connect
    self._conn = self.get_connection()
  File "/home/attiq/frappe-bench/apps/frappe/frappe/database/mariadb/database.py", line 90, in get_connection
    local_infile = frappe.conf.local_infile)
  File "/home/attiq/frappe-bench/env/lib/python3.6/site-packages/pymysql/__init__.py", line 94, in Connect
    return Connection(*args, **kwargs)
  File "/home/attiq/frappe-bench/env/lib/python3.6/site-packages/pymysql/connections.py", line 325, in __init__
    self.connect()
  File "/home/attiq/frappe-bench/env/lib/python3.6/site-packages/pymysql/connections.py", line 630, in connect
    raise exc
pymysql.err.OperationalError: (2003, "Can't connect to MySQL server on '192.168.2.219' (timed out)")

[ERROR] 2021-09-22 22:16:45,419 | /home/attiq/frappe-bench/apps/frappe/frappe/utils/scheduler.py:
Site: gourmet.nerp
Exception in Enqueue Events for Site gourmet.nerp
Traceback (most recent call last):
  File "/home/attiq/frappe-bench/env/lib/python3.6/site-packages/pymysql/connections.py", line 583, in connect
    **kwargs)
  File "/usr/lib/python3.6/socket.py", line 724, in create_connection
    raise err
  File "/usr/lib/python3.6/socket.py", line 713, in create_connection
    sock.connect(sa)
socket.timeout: timed out

During handling of the above exception, another exception occurred:

Traceback (most recent call last):
  File "/home/attiq/frappe-bench/apps/frappe/frappe/utils/scheduler.py", line 81, in enqueue_events_for_site
    if is_scheduler_inactive():
  File "/home/attiq/frappe-bench/apps/frappe/frappe/utils/scheduler.py", line 228, in is_scheduler_inactive
    if is_scheduler_disabled():
  File "/home/attiq/frappe-bench/apps/frappe/frappe/utils/scheduler.py", line 237, in is_scheduler_disabled
    return not frappe.utils.cint(frappe.db.get_single_value("System Settings", "enable_scheduler"))
  File "/home/attiq/frappe-bench/apps/frappe/frappe/database/database.py", line 553, in get_single_value
    `tabSingles` where `doctype`=%s and `field`=%s""", (doctype, fieldname))
  File "/home/attiq/frappe-bench/apps/frappe/frappe/database/database.py", line 122, in sql
    self.connect()
  File "/home/attiq/frappe-bench/apps/frappe/frappe/database/database.py", line 75, in connect
    self._conn = self.get_connection()
  File "/home/attiq/frappe-bench/apps/frappe/frappe/database/mariadb/database.py", line 90, in get_connection
    local_infile = frappe.conf.local_infile)
  File "/home/attiq/frappe-bench/env/lib/python3.6/site-packages/pymysql/__init__.py", line 94, in Connect
    return Connection(*args, **kwargs)
  File "/home/attiq/frappe-bench/env/lib/python3.6/site-packages/pymysql/connections.py", line 325, in __init__
    self.connect()
  File "/home/attiq/frappe-bench/env/lib/python3.6/site-packages/pymysql/connections.py", line 630, in connect
    raise exc
pymysql.err.OperationalError: (2003, "Can't connect to MySQL server on '192.168.2.79' (timed out)")

[ERROR] 2021-09-22 22:16:55,433 | /home/attiq/frappe-bench/apps/frappe/frappe/utils/scheduler.py:
Site: gourmet.nrp
Exception in Enqueue Events for Site gourmet.nrp
Traceback (most recent call last):
  File "/home/attiq/frappe-bench/env/lib/python3.6/site-packages/pymysql/connections.py", line 583, in connect
    **kwargs)
  File "/usr/lib/python3.6/socket.py", line 724, in create_connection
    raise err
  File "/usr/lib/python3.6/socket.py", line 713, in create_connection
    sock.connect(sa)
socket.timeout: timed out

During handling of the above exception, another exception occurred:

Traceback (most recent call last):
  File "/home/attiq/frappe-bench/apps/frappe/frappe/utils/scheduler.py", line 81, in enqueue_events_for_site
    if is_scheduler_inactive():
  File "/home/attiq/frappe-bench/apps/frappe/frappe/utils/scheduler.py", line 228, in is_scheduler_inactive
    if is_scheduler_disabled():
  File "/home/attiq/frappe-bench/apps/frappe/frappe/utils/scheduler.py", line 237, in is_scheduler_disabled
    return not frappe.utils.cint(frappe.db.get_single_value("System Settings", "enable_scheduler"))
  File "/home/attiq/frappe-bench/apps/frappe/frappe/database/database.py", line 553, in get_single_value
    `tabSingles` where `doctype`=%s and `field`=%s""", (doctype, fieldname))
  File "/home/attiq/frappe-bench/apps/frappe/frappe/database/database.py", line 122, in sql
    self.connect()
  File "/home/attiq/frappe-bench/apps/frappe/frappe/database/database.py", line 75, in connect
    self._conn = self.get_connection()
  File "/home/attiq/frappe-bench/apps/frappe/frappe/database/mariadb/database.py", line 90, in get_connection
    local_infile = frappe.conf.local_infile)
  File "/home/attiq/frappe-bench/env/lib/python3.6/site-packages/pymysql/__init__.py", line 94, in Connect
    return Connection(*args, **kwargs)
  File "/home/attiq/frappe-bench/env/lib/python3.6/site-packages/pymysql/connections.py", line 325, in __init__
    self.connect()
  File "/home/attiq/frappe-bench/env/lib/python3.6/site-packages/pymysql/connections.py", line 630, in connect
    raise exc
pymysql.err.OperationalError: (2003, "Can't connect to MySQL server on '192.168.2.219' (timed out)")

[ERROR] 2021-09-22 22:17:05,446 | /home/attiq/frappe-bench/apps/frappe/frappe/utils/scheduler.py:
Site: local.nerp
Exception in Enqueue Events for Site local.nerp
Traceback (most recent call last):
  File "/home/attiq/frappe-bench/env/lib/python3.6/site-packages/pymysql/connections.py", line 583, in connect
    **kwargs)
  File "/usr/lib/python3.6/socket.py", line 724, in create_connection
    raise err
  File "/usr/lib/python3.6/socket.py", line 713, in create_connection
    sock.connect(sa)
socket.timeout: timed out

During handling of the above exception, another exception occurred:

Traceback (most recent call last):
  File "/home/attiq/frappe-bench/apps/frappe/frappe/utils/scheduler.py", line 81, in enqueue_events_for_site
    if is_scheduler_inactive():
  File "/home/attiq/frappe-bench/apps/frappe/frappe/utils/scheduler.py", line 228, in is_scheduler_inactive
    if is_scheduler_disabled():
  File "/home/attiq/frappe-bench/apps/frappe/frappe/utils/scheduler.py", line 237, in is_scheduler_disabled
    return not frappe.utils.cint(frappe.db.get_single_value("System Settings", "enable_scheduler"))
  File "/home/attiq/frappe-bench/apps/frappe/frappe/database/database.py", line 553, in get_single_value
    `tabSingles` where `doctype`=%s and `field`=%s""", (doctype, fieldname))
  File "/home/attiq/frappe-bench/apps/frappe/frappe/database/database.py", line 122, in sql
    self.connect()
  File "/home/attiq/frappe-bench/apps/frappe/frappe/database/database.py", line 75, in connect
    self._conn = self.get_connection()
  File "/home/attiq/frappe-bench/apps/frappe/frappe/database/mariadb/database.py", line 90, in get_connection
    local_infile = frappe.conf.local_infile)
  File "/home/attiq/frappe-bench/env/lib/python3.6/site-packages/pymysql/__init__.py", line 94, in Connect
    return Connection(*args, **kwargs)
  File "/home/attiq/frappe-bench/env/lib/python3.6/site-packages/pymysql/connections.py", line 325, in __init__
    self.connect()
  File "/home/attiq/frappe-bench/env/lib/python3.6/site-packages/pymysql/connections.py", line 630, in connect
    raise exc
pymysql.err.OperationalError: (2003, "Can't connect to MySQL server on '192.168.2.219' (timed out)")

[ERROR] 2021-09-23 10:56:16,184 | /home/attiq/frappe-bench/apps/frappe/frappe/utils/scheduler.py:
Site: erp.sample
Exception in Enqueue Events for Site erp.sample
Traceback (most recent call last):
  File "/home/attiq/frappe-bench/env/lib/python3.6/site-packages/pymysql/connections.py", line 583, in connect
    **kwargs)
  File "/usr/lib/python3.6/socket.py", line 724, in create_connection
    raise err
  File "/usr/lib/python3.6/socket.py", line 713, in create_connection
    sock.connect(sa)
OSError: [Errno 101] Network is unreachable

During handling of the above exception, another exception occurred:

Traceback (most recent call last):
  File "/home/attiq/frappe-bench/apps/frappe/frappe/utils/scheduler.py", line 81, in enqueue_events_for_site
    if is_scheduler_inactive():
  File "/home/attiq/frappe-bench/apps/frappe/frappe/utils/scheduler.py", line 228, in is_scheduler_inactive
    if is_scheduler_disabled():
  File "/home/attiq/frappe-bench/apps/frappe/frappe/utils/scheduler.py", line 237, in is_scheduler_disabled
    return not frappe.utils.cint(frappe.db.get_single_value("System Settings", "enable_scheduler"))
  File "/home/attiq/frappe-bench/apps/frappe/frappe/database/database.py", line 553, in get_single_value
    `tabSingles` where `doctype`=%s and `field`=%s""", (doctype, fieldname))
  File "/home/attiq/frappe-bench/apps/frappe/frappe/database/database.py", line 122, in sql
    self.connect()
  File "/home/attiq/frappe-bench/apps/frappe/frappe/database/database.py", line 75, in connect
    self._conn = self.get_connection()
  File "/home/attiq/frappe-bench/apps/frappe/frappe/database/mariadb/database.py", line 90, in get_connection
    local_infile = frappe.conf.local_infile)
  File "/home/attiq/frappe-bench/env/lib/python3.6/site-packages/pymysql/__init__.py", line 94, in Connect
    return Connection(*args, **kwargs)
  File "/home/attiq/frappe-bench/env/lib/python3.6/site-packages/pymysql/connections.py", line 325, in __init__
    self.connect()
  File "/home/attiq/frappe-bench/env/lib/python3.6/site-packages/pymysql/connections.py", line 630, in connect
    raise exc
pymysql.err.OperationalError: (2003, "Can't connect to MySQL server on '192.168.2.219' ([Errno 101] Network is unreachable)")

[ERROR] 2021-09-23 10:56:16,185 | /home/attiq/frappe-bench/apps/frappe/frappe/utils/scheduler.py:
Site: foo.bar
Exception in Enqueue Events for Site foo.bar
Traceback (most recent call last):
  File "/home/attiq/frappe-bench/env/lib/python3.6/site-packages/pymysql/connections.py", line 583, in connect
    **kwargs)
  File "/usr/lib/python3.6/socket.py", line 724, in create_connection
    raise err
  File "/usr/lib/python3.6/socket.py", line 713, in create_connection
    sock.connect(sa)
OSError: [Errno 101] Network is unreachable

During handling of the above exception, another exception occurred:

Traceback (most recent call last):
  File "/home/attiq/frappe-bench/apps/frappe/frappe/utils/scheduler.py", line 81, in enqueue_events_for_site
    if is_scheduler_inactive():
  File "/home/attiq/frappe-bench/apps/frappe/frappe/utils/scheduler.py", line 228, in is_scheduler_inactive
    if is_scheduler_disabled():
  File "/home/attiq/frappe-bench/apps/frappe/frappe/utils/scheduler.py", line 237, in is_scheduler_disabled
    return not frappe.utils.cint(frappe.db.get_single_value("System Settings", "enable_scheduler"))
  File "/home/attiq/frappe-bench/apps/frappe/frappe/database/database.py", line 553, in get_single_value
    `tabSingles` where `doctype`=%s and `field`=%s""", (doctype, fieldname))
  File "/home/attiq/frappe-bench/apps/frappe/frappe/database/database.py", line 122, in sql
    self.connect()
  File "/home/attiq/frappe-bench/apps/frappe/frappe/database/database.py", line 75, in connect
    self._conn = self.get_connection()
  File "/home/attiq/frappe-bench/apps/frappe/frappe/database/mariadb/database.py", line 90, in get_connection
    local_infile = frappe.conf.local_infile)
  File "/home/attiq/frappe-bench/env/lib/python3.6/site-packages/pymysql/__init__.py", line 94, in Connect
    return Connection(*args, **kwargs)
  File "/home/attiq/frappe-bench/env/lib/python3.6/site-packages/pymysql/connections.py", line 325, in __init__
    self.connect()
  File "/home/attiq/frappe-bench/env/lib/python3.6/site-packages/pymysql/connections.py", line 630, in connect
    raise exc
pymysql.err.OperationalError: (2003, "Can't connect to MySQL server on '192.168.2.219' ([Errno 101] Network is unreachable)")

[ERROR] 2021-09-23 10:56:16,186 | /home/attiq/frappe-bench/apps/frappe/frappe/utils/scheduler.py:
Site: gourmet.nerp
Exception in Enqueue Events for Site gourmet.nerp
Traceback (most recent call last):
  File "/home/attiq/frappe-bench/env/lib/python3.6/site-packages/pymysql/connections.py", line 583, in connect
    **kwargs)
  File "/usr/lib/python3.6/socket.py", line 724, in create_connection
    raise err
  File "/usr/lib/python3.6/socket.py", line 713, in create_connection
    sock.connect(sa)
OSError: [Errno 101] Network is unreachable

During handling of the above exception, another exception occurred:

Traceback (most recent call last):
  File "/home/attiq/frappe-bench/apps/frappe/frappe/utils/scheduler.py", line 81, in enqueue_events_for_site
    if is_scheduler_inactive():
  File "/home/attiq/frappe-bench/apps/frappe/frappe/utils/scheduler.py", line 228, in is_scheduler_inactive
    if is_scheduler_disabled():
  File "/home/attiq/frappe-bench/apps/frappe/frappe/utils/scheduler.py", line 237, in is_scheduler_disabled
    return not frappe.utils.cint(frappe.db.get_single_value("System Settings", "enable_scheduler"))
  File "/home/attiq/frappe-bench/apps/frappe/frappe/database/database.py", line 553, in get_single_value
    `tabSingles` where `doctype`=%s and `field`=%s""", (doctype, fieldname))
  File "/home/attiq/frappe-bench/apps/frappe/frappe/database/database.py", line 122, in sql
    self.connect()
  File "/home/attiq/frappe-bench/apps/frappe/frappe/database/database.py", line 75, in connect
    self._conn = self.get_connection()
  File "/home/attiq/frappe-bench/apps/frappe/frappe/database/mariadb/database.py", line 90, in get_connection
    local_infile = frappe.conf.local_infile)
  File "/home/attiq/frappe-bench/env/lib/python3.6/site-packages/pymysql/__init__.py", line 94, in Connect
    return Connection(*args, **kwargs)
  File "/home/attiq/frappe-bench/env/lib/python3.6/site-packages/pymysql/connections.py", line 325, in __init__
    self.connect()
  File "/home/attiq/frappe-bench/env/lib/python3.6/site-packages/pymysql/connections.py", line 630, in connect
    raise exc
pymysql.err.OperationalError: (2003, "Can't connect to MySQL server on '192.168.2.79' ([Errno 101] Network is unreachable)")

[ERROR] 2021-09-23 10:56:16,187 | /home/attiq/frappe-bench/apps/frappe/frappe/utils/scheduler.py:
Site: gourmet.nrp
Exception in Enqueue Events for Site gourmet.nrp
Traceback (most recent call last):
  File "/home/attiq/frappe-bench/env/lib/python3.6/site-packages/pymysql/connections.py", line 583, in connect
    **kwargs)
  File "/usr/lib/python3.6/socket.py", line 724, in create_connection
    raise err
  File "/usr/lib/python3.6/socket.py", line 713, in create_connection
    sock.connect(sa)
OSError: [Errno 101] Network is unreachable

During handling of the above exception, another exception occurred:

Traceback (most recent call last):
  File "/home/attiq/frappe-bench/apps/frappe/frappe/utils/scheduler.py", line 81, in enqueue_events_for_site
    if is_scheduler_inactive():
  File "/home/attiq/frappe-bench/apps/frappe/frappe/utils/scheduler.py", line 228, in is_scheduler_inactive
    if is_scheduler_disabled():
  File "/home/attiq/frappe-bench/apps/frappe/frappe/utils/scheduler.py", line 237, in is_scheduler_disabled
    return not frappe.utils.cint(frappe.db.get_single_value("System Settings", "enable_scheduler"))
  File "/home/attiq/frappe-bench/apps/frappe/frappe/database/database.py", line 553, in get_single_value
    `tabSingles` where `doctype`=%s and `field`=%s""", (doctype, fieldname))
  File "/home/attiq/frappe-bench/apps/frappe/frappe/database/database.py", line 122, in sql
    self.connect()
  File "/home/attiq/frappe-bench/apps/frappe/frappe/database/database.py", line 75, in connect
    self._conn = self.get_connection()
  File "/home/attiq/frappe-bench/apps/frappe/frappe/database/mariadb/database.py", line 90, in get_connection
    local_infile = frappe.conf.local_infile)
  File "/home/attiq/frappe-bench/env/lib/python3.6/site-packages/pymysql/__init__.py", line 94, in Connect
    return Connection(*args, **kwargs)
  File "/home/attiq/frappe-bench/env/lib/python3.6/site-packages/pymysql/connections.py", line 325, in __init__
    self.connect()
  File "/home/attiq/frappe-bench/env/lib/python3.6/site-packages/pymysql/connections.py", line 630, in connect
    raise exc
pymysql.err.OperationalError: (2003, "Can't connect to MySQL server on '192.168.2.219' ([Errno 101] Network is unreachable)")

[ERROR] 2021-09-23 10:56:16,188 | /home/attiq/frappe-bench/apps/frappe/frappe/utils/scheduler.py:
Site: local.nerp
Exception in Enqueue Events for Site local.nerp
Traceback (most recent call last):
  File "/home/attiq/frappe-bench/env/lib/python3.6/site-packages/pymysql/connections.py", line 583, in connect
    **kwargs)
  File "/usr/lib/python3.6/socket.py", line 724, in create_connection
    raise err
  File "/usr/lib/python3.6/socket.py", line 713, in create_connection
    sock.connect(sa)
OSError: [Errno 101] Network is unreachable

During handling of the above exception, another exception occurred:

Traceback (most recent call last):
  File "/home/attiq/frappe-bench/apps/frappe/frappe/utils/scheduler.py", line 81, in enqueue_events_for_site
    if is_scheduler_inactive():
  File "/home/attiq/frappe-bench/apps/frappe/frappe/utils/scheduler.py", line 228, in is_scheduler_inactive
    if is_scheduler_disabled():
  File "/home/attiq/frappe-bench/apps/frappe/frappe/utils/scheduler.py", line 237, in is_scheduler_disabled
    return not frappe.utils.cint(frappe.db.get_single_value("System Settings", "enable_scheduler"))
  File "/home/attiq/frappe-bench/apps/frappe/frappe/database/database.py", line 553, in get_single_value
    `tabSingles` where `doctype`=%s and `field`=%s""", (doctype, fieldname))
  File "/home/attiq/frappe-bench/apps/frappe/frappe/database/database.py", line 122, in sql
    self.connect()
  File "/home/attiq/frappe-bench/apps/frappe/frappe/database/database.py", line 75, in connect
    self._conn = self.get_connection()
  File "/home/attiq/frappe-bench/apps/frappe/frappe/database/mariadb/database.py", line 90, in get_connection
    local_infile = frappe.conf.local_infile)
  File "/home/attiq/frappe-bench/env/lib/python3.6/site-packages/pymysql/__init__.py", line 94, in Connect
    return Connection(*args, **kwargs)
  File "/home/attiq/frappe-bench/env/lib/python3.6/site-packages/pymysql/connections.py", line 325, in __init__
    self.connect()
  File "/home/attiq/frappe-bench/env/lib/python3.6/site-packages/pymysql/connections.py", line 630, in connect
    raise exc
pymysql.err.OperationalError: (2003, "Can't connect to MySQL server on '192.168.2.219' ([Errno 101] Network is unreachable)")

[DEBUG] 2021-09-23 10:57:16,262 | /home/attiq/frappe-bench/apps/frappe/frappe/utils/scheduler.py:
Site: erp.sample
Access denied for site erp.sample
[DEBUG] 2021-09-23 10:57:16,267 | /home/attiq/frappe-bench/apps/frappe/frappe/utils/scheduler.py:
Site: foo.bar
Access denied for site foo.bar
[DEBUG] 2021-09-23 10:57:16,317 | /home/attiq/frappe-bench/apps/frappe/frappe/utils/scheduler.py:
Site: gourmet.nerp
Queued events for site gourmet.nerp
[DEBUG] 2021-09-23 10:57:16,322 | /home/attiq/frappe-bench/apps/frappe/frappe/utils/scheduler.py:
Site: gourmet.nrp
Access denied for site gourmet.nrp
[DEBUG] 2021-09-23 10:57:16,326 | /home/attiq/frappe-bench/apps/frappe/frappe/utils/scheduler.py:
Site: local.nerp
Access denied for site local.nerp
[DEBUG] 2021-09-23 10:58:16,399 | /home/attiq/frappe-bench/apps/frappe/frappe/utils/scheduler.py:
Site: erp.sample
Access denied for site erp.sample
[DEBUG] 2021-09-23 10:58:16,404 | /home/attiq/frappe-bench/apps/frappe/frappe/utils/scheduler.py:
Site: foo.bar
Access denied for site foo.bar
[DEBUG] 2021-09-23 10:58:16,452 | /home/attiq/frappe-bench/apps/frappe/frappe/utils/scheduler.py:
Site: gourmet.nerp
Queued events for site gourmet.nerp
[DEBUG] 2021-09-23 10:58:16,457 | /home/attiq/frappe-bench/apps/frappe/frappe/utils/scheduler.py:
Site: gourmet.nrp
Access denied for site gourmet.nrp
[DEBUG] 2021-09-23 10:58:16,461 | /home/attiq/frappe-bench/apps/frappe/frappe/utils/scheduler.py:
Site: local.nerp
Access denied for site local.nerp
[DEBUG] 2021-09-23 10:59:16,526 | /home/attiq/frappe-bench/apps/frappe/frappe/utils/scheduler.py:
Site: erp.sample
Access denied for site erp.sample
[DEBUG] 2021-09-23 10:59:16,529 | /home/attiq/frappe-bench/apps/frappe/frappe/utils/scheduler.py:
Site: foo.bar
Access denied for site foo.bar
[DEBUG] 2021-09-23 10:59:16,572 | /home/attiq/frappe-bench/apps/frappe/frappe/utils/scheduler.py:
Site: gourmet.nerp
Queued events for site gourmet.nerp
[DEBUG] 2021-09-23 10:59:16,577 | /home/attiq/frappe-bench/apps/frappe/frappe/utils/scheduler.py:
Site: gourmet.nrp
Access denied for site gourmet.nrp
[DEBUG] 2021-09-23 10:59:16,581 | /home/attiq/frappe-bench/apps/frappe/frappe/utils/scheduler.py:
Site: local.nerp
Access denied for site local.nerp
[DEBUG] 2021-09-23 11:00:16,651 | /home/attiq/frappe-bench/apps/frappe/frappe/utils/scheduler.py:
Site: erp.sample
Access denied for site erp.sample
[DEBUG] 2021-09-23 11:00:16,657 | /home/attiq/frappe-bench/apps/frappe/frappe/utils/scheduler.py:
Site: foo.bar
Access denied for site foo.bar
[DEBUG] 2021-09-23 11:00:16,730 | /home/attiq/frappe-bench/apps/frappe/frappe/utils/scheduler.py:
Site: gourmet.nerp
Queued events for site gourmet.nerp
[DEBUG] 2021-09-23 11:00:16,733 | /home/attiq/frappe-bench/apps/frappe/frappe/utils/scheduler.py:
Site: gourmet.nrp
Access denied for site gourmet.nrp
[DEBUG] 2021-09-23 11:00:16,737 | /home/attiq/frappe-bench/apps/frappe/frappe/utils/scheduler.py:
Site: local.nerp
Access denied for site local.nerp
[DEBUG] 2021-09-23 11:01:16,804 | /home/attiq/frappe-bench/apps/frappe/frappe/utils/scheduler.py:
Site: erp.sample
Access denied for site erp.sample
[DEBUG] 2021-09-23 11:01:16,808 | /home/attiq/frappe-bench/apps/frappe/frappe/utils/scheduler.py:
Site: foo.bar
Access denied for site foo.bar
[DEBUG] 2021-09-23 11:01:16,840 | /home/attiq/frappe-bench/apps/frappe/frappe/utils/scheduler.py:
Site: gourmet.nerp
Queued events for site gourmet.nerp
[DEBUG] 2021-09-23 11:01:16,844 | /home/attiq/frappe-bench/apps/frappe/frappe/utils/scheduler.py:
Site: gourmet.nrp
Access denied for site gourmet.nrp
[DEBUG] 2021-09-23 11:01:16,847 | /home/attiq/frappe-bench/apps/frappe/frappe/utils/scheduler.py:
Site: local.nerp
Access denied for site local.nerp
[DEBUG] 2021-09-23 11:02:16,918 | /home/attiq/frappe-bench/apps/frappe/frappe/utils/scheduler.py:
Site: erp.sample
Access denied for site erp.sample
[DEBUG] 2021-09-23 11:02:16,922 | /home/attiq/frappe-bench/apps/frappe/frappe/utils/scheduler.py:
Site: foo.bar
Access denied for site foo.bar
[DEBUG] 2021-09-23 11:02:16,968 | /home/attiq/frappe-bench/apps/frappe/frappe/utils/scheduler.py:
Site: gourmet.nerp
Queued events for site gourmet.nerp
[DEBUG] 2021-09-23 11:02:16,972 | /home/attiq/frappe-bench/apps/frappe/frappe/utils/scheduler.py:
Site: gourmet.nrp
Access denied for site gourmet.nrp
[DEBUG] 2021-09-23 11:02:16,977 | /home/attiq/frappe-bench/apps/frappe/frappe/utils/scheduler.py:
Site: local.nerp
Access denied for site local.nerp
