[ERROR] 2021-11-30 11:26:06,868 | /home/attiq/frappe-bench/apps/frappe/frappe/utils/scheduler.py:
Site: foo.bar
Exception in Enqueue Events for Site foo.bar
Traceback (most recent call last):
  File "/home/attiq/frappe-bench/env/lib/python3.6/site-packages/pymysql/connections.py", line 583, in connect
    **kwargs)
  File "/usr/lib/python3.6/socket.py", line 724, in create_connection
    raise err
  File "/usr/lib/python3.6/socket.py", line 713, in create_connection
    sock.connect(sa)
socket.timeout: timed out

During handling of the above exception, another exception occurred:

Traceback (most recent call last):
  File "/home/attiq/frappe-bench/apps/frappe/frappe/utils/scheduler.py", line 81, in enqueue_events_for_site
    if is_scheduler_inactive():
  File "/home/attiq/frappe-bench/apps/frappe/frappe/utils/scheduler.py", line 228, in is_scheduler_inactive
    if is_scheduler_disabled():
  File "/home/attiq/frappe-bench/apps/frappe/frappe/utils/scheduler.py", line 237, in is_scheduler_disabled
    return not frappe.utils.cint(frappe.db.get_single_value("System Settings", "enable_scheduler"))
  File "/home/attiq/frappe-bench/apps/frappe/frappe/database/database.py", line 553, in get_single_value
    `tabSingles` where `doctype`=%s and `field`=%s""", (doctype, fieldname))
  File "/home/attiq/frappe-bench/apps/frappe/frappe/database/database.py", line 122, in sql
    self.connect()
  File "/home/attiq/frappe-bench/apps/frappe/frappe/database/database.py", line 75, in connect
    self._conn = self.get_connection()
  File "/home/attiq/frappe-bench/apps/frappe/frappe/database/mariadb/database.py", line 90, in get_connection
    local_infile = frappe.conf.local_infile)
  File "/home/attiq/frappe-bench/env/lib/python3.6/site-packages/pymysql/__init__.py", line 94, in Connect
    return Connection(*args, **kwargs)
  File "/home/attiq/frappe-bench/env/lib/python3.6/site-packages/pymysql/connections.py", line 325, in __init__
    self.connect()
  File "/home/attiq/frappe-bench/env/lib/python3.6/site-packages/pymysql/connections.py", line 630, in connect
    raise exc
pymysql.err.OperationalError: (2003, "Can't connect to MySQL server on '192.168.2.219' (timed out)")

[DEBUG] 2021-11-30 11:26:06,920 | /home/attiq/frappe-bench/apps/frappe/frappe/utils/scheduler.py:
Site: gourmet.nerp
Queued events for site gourmet.nerp
[ERROR] 2021-11-30 11:26:16,925 | /home/attiq/frappe-bench/apps/frappe/frappe/utils/scheduler.py:
Site: gourmet.nrp
Exception in Enqueue Events for Site gourmet.nrp
Traceback (most recent call last):
  File "/home/attiq/frappe-bench/env/lib/python3.6/site-packages/pymysql/connections.py", line 583, in connect
    **kwargs)
  File "/usr/lib/python3.6/socket.py", line 724, in create_connection
    raise err
  File "/usr/lib/python3.6/socket.py", line 713, in create_connection
    sock.connect(sa)
socket.timeout: timed out

During handling of the above exception, another exception occurred:

Traceback (most recent call last):
  File "/home/attiq/frappe-bench/apps/frappe/frappe/utils/scheduler.py", line 81, in enqueue_events_for_site
    if is_scheduler_inactive():
  File "/home/attiq/frappe-bench/apps/frappe/frappe/utils/scheduler.py", line 228, in is_scheduler_inactive
    if is_scheduler_disabled():
  File "/home/attiq/frappe-bench/apps/frappe/frappe/utils/scheduler.py", line 237, in is_scheduler_disabled
    return not frappe.utils.cint(frappe.db.get_single_value("System Settings", "enable_scheduler"))
  File "/home/attiq/frappe-bench/apps/frappe/frappe/database/database.py", line 553, in get_single_value
    `tabSingles` where `doctype`=%s and `field`=%s""", (doctype, fieldname))
  File "/home/attiq/frappe-bench/apps/frappe/frappe/database/database.py", line 122, in sql
    self.connect()
  File "/home/attiq/frappe-bench/apps/frappe/frappe/database/database.py", line 75, in connect
    self._conn = self.get_connection()
  File "/home/attiq/frappe-bench/apps/frappe/frappe/database/mariadb/database.py", line 90, in get_connection
    local_infile = frappe.conf.local_infile)
  File "/home/attiq/frappe-bench/env/lib/python3.6/site-packages/pymysql/__init__.py", line 94, in Connect
    return Connection(*args, **kwargs)
  File "/home/attiq/frappe-bench/env/lib/python3.6/site-packages/pymysql/connections.py", line 325, in __init__
    self.connect()
  File "/home/attiq/frappe-bench/env/lib/python3.6/site-packages/pymysql/connections.py", line 630, in connect
    raise exc
pymysql.err.OperationalError: (2003, "Can't connect to MySQL server on '192.168.2.219' (timed out)")

[ERROR] 2021-11-30 11:26:26,936 | /home/attiq/frappe-bench/apps/frappe/frappe/utils/scheduler.py:
Site: local.nerp
Exception in Enqueue Events for Site local.nerp
Traceback (most recent call last):
  File "/home/attiq/frappe-bench/env/lib/python3.6/site-packages/pymysql/connections.py", line 583, in connect
    **kwargs)
  File "/usr/lib/python3.6/socket.py", line 724, in create_connection
    raise err
  File "/usr/lib/python3.6/socket.py", line 713, in create_connection
    sock.connect(sa)
socket.timeout: timed out

During handling of the above exception, another exception occurred:

Traceback (most recent call last):
  File "/home/attiq/frappe-bench/apps/frappe/frappe/utils/scheduler.py", line 81, in enqueue_events_for_site
    if is_scheduler_inactive():
  File "/home/attiq/frappe-bench/apps/frappe/frappe/utils/scheduler.py", line 228, in is_scheduler_inactive
    if is_scheduler_disabled():
  File "/home/attiq/frappe-bench/apps/frappe/frappe/utils/scheduler.py", line 237, in is_scheduler_disabled
    return not frappe.utils.cint(frappe.db.get_single_value("System Settings", "enable_scheduler"))
  File "/home/attiq/frappe-bench/apps/frappe/frappe/database/database.py", line 553, in get_single_value
    `tabSingles` where `doctype`=%s and `field`=%s""", (doctype, fieldname))
  File "/home/attiq/frappe-bench/apps/frappe/frappe/database/database.py", line 122, in sql
    self.connect()
  File "/home/attiq/frappe-bench/apps/frappe/frappe/database/database.py", line 75, in connect
    self._conn = self.get_connection()
  File "/home/attiq/frappe-bench/apps/frappe/frappe/database/mariadb/database.py", line 90, in get_connection
    local_infile = frappe.conf.local_infile)
  File "/home/attiq/frappe-bench/env/lib/python3.6/site-packages/pymysql/__init__.py", line 94, in Connect
    return Connection(*args, **kwargs)
  File "/home/attiq/frappe-bench/env/lib/python3.6/site-packages/pymysql/connections.py", line 325, in __init__
    self.connect()
  File "/home/attiq/frappe-bench/env/lib/python3.6/site-packages/pymysql/connections.py", line 630, in connect
    raise exc
pymysql.err.OperationalError: (2003, "Can't connect to MySQL server on '192.168.2.219' (timed out)")

[ERROR] 2021-11-30 11:27:37,010 | /home/attiq/frappe-bench/apps/frappe/frappe/utils/scheduler.py:
Site: erp.sample
Exception in Enqueue Events for Site erp.sample
Traceback (most recent call last):
  File "/home/attiq/frappe-bench/env/lib/python3.6/site-packages/pymysql/connections.py", line 583, in connect
    **kwargs)
  File "/usr/lib/python3.6/socket.py", line 724, in create_connection
    raise err
  File "/usr/lib/python3.6/socket.py", line 713, in create_connection
    sock.connect(sa)
socket.timeout: timed out

During handling of the above exception, another exception occurred:

Traceback (most recent call last):
  File "/home/attiq/frappe-bench/apps/frappe/frappe/utils/scheduler.py", line 81, in enqueue_events_for_site
    if is_scheduler_inactive():
  File "/home/attiq/frappe-bench/apps/frappe/frappe/utils/scheduler.py", line 228, in is_scheduler_inactive
    if is_scheduler_disabled():
  File "/home/attiq/frappe-bench/apps/frappe/frappe/utils/scheduler.py", line 237, in is_scheduler_disabled
    return not frappe.utils.cint(frappe.db.get_single_value("System Settings", "enable_scheduler"))
  File "/home/attiq/frappe-bench/apps/frappe/frappe/database/database.py", line 553, in get_single_value
    `tabSingles` where `doctype`=%s and `field`=%s""", (doctype, fieldname))
  File "/home/attiq/frappe-bench/apps/frappe/frappe/database/database.py", line 122, in sql
    self.connect()
  File "/home/attiq/frappe-bench/apps/frappe/frappe/database/database.py", line 75, in connect
    self._conn = self.get_connection()
  File "/home/attiq/frappe-bench/apps/frappe/frappe/database/mariadb/database.py", line 90, in get_connection
    local_infile = frappe.conf.local_infile)
  File "/home/attiq/frappe-bench/env/lib/python3.6/site-packages/pymysql/__init__.py", line 94, in Connect
    return Connection(*args, **kwargs)
  File "/home/attiq/frappe-bench/env/lib/python3.6/site-packages/pymysql/connections.py", line 325, in __init__
    self.connect()
  File "/home/attiq/frappe-bench/env/lib/python3.6/site-packages/pymysql/connections.py", line 630, in connect
    raise exc
pymysql.err.OperationalError: (2003, "Can't connect to MySQL server on '192.168.2.219' (timed out)")

[ERROR] 2021-11-30 11:27:47,020 | /home/attiq/frappe-bench/apps/frappe/frappe/utils/scheduler.py:
Site: foo.bar
Exception in Enqueue Events for Site foo.bar
Traceback (most recent call last):
  File "/home/attiq/frappe-bench/env/lib/python3.6/site-packages/pymysql/connections.py", line 583, in connect
    **kwargs)
  File "/usr/lib/python3.6/socket.py", line 724, in create_connection
    raise err
  File "/usr/lib/python3.6/socket.py", line 713, in create_connection
    sock.connect(sa)
socket.timeout: timed out

During handling of the above exception, another exception occurred:

Traceback (most recent call last):
  File "/home/attiq/frappe-bench/apps/frappe/frappe/utils/scheduler.py", line 81, in enqueue_events_for_site
    if is_scheduler_inactive():
  File "/home/attiq/frappe-bench/apps/frappe/frappe/utils/scheduler.py", line 228, in is_scheduler_inactive
    if is_scheduler_disabled():
  File "/home/attiq/frappe-bench/apps/frappe/frappe/utils/scheduler.py", line 237, in is_scheduler_disabled
    return not frappe.utils.cint(frappe.db.get_single_value("System Settings", "enable_scheduler"))
  File "/home/attiq/frappe-bench/apps/frappe/frappe/database/database.py", line 553, in get_single_value
    `tabSingles` where `doctype`=%s and `field`=%s""", (doctype, fieldname))
  File "/home/attiq/frappe-bench/apps/frappe/frappe/database/database.py", line 122, in sql
    self.connect()
  File "/home/attiq/frappe-bench/apps/frappe/frappe/database/database.py", line 75, in connect
    self._conn = self.get_connection()
  File "/home/attiq/frappe-bench/apps/frappe/frappe/database/mariadb/database.py", line 90, in get_connection
    local_infile = frappe.conf.local_infile)
  File "/home/attiq/frappe-bench/env/lib/python3.6/site-packages/pymysql/__init__.py", line 94, in Connect
    return Connection(*args, **kwargs)
  File "/home/attiq/frappe-bench/env/lib/python3.6/site-packages/pymysql/connections.py", line 325, in __init__
    self.connect()
  File "/home/attiq/frappe-bench/env/lib/python3.6/site-packages/pymysql/connections.py", line 630, in connect
    raise exc
pymysql.err.OperationalError: (2003, "Can't connect to MySQL server on '192.168.2.219' (timed out)")

[DEBUG] 2021-11-30 11:27:47,099 | /home/attiq/frappe-bench/apps/frappe/frappe/utils/scheduler.py:
Site: gourmet.nerp
Queued events for site gourmet.nerp
[ERROR] 2021-11-30 11:27:57,107 | /home/attiq/frappe-bench/apps/frappe/frappe/utils/scheduler.py:
Site: gourmet.nrp
Exception in Enqueue Events for Site gourmet.nrp
Traceback (most recent call last):
  File "/home/attiq/frappe-bench/env/lib/python3.6/site-packages/pymysql/connections.py", line 583, in connect
    **kwargs)
  File "/usr/lib/python3.6/socket.py", line 724, in create_connection
    raise err
  File "/usr/lib/python3.6/socket.py", line 713, in create_connection
    sock.connect(sa)
socket.timeout: timed out

During handling of the above exception, another exception occurred:

Traceback (most recent call last):
  File "/home/attiq/frappe-bench/apps/frappe/frappe/utils/scheduler.py", line 81, in enqueue_events_for_site
    if is_scheduler_inactive():
  File "/home/attiq/frappe-bench/apps/frappe/frappe/utils/scheduler.py", line 228, in is_scheduler_inactive
    if is_scheduler_disabled():
  File "/home/attiq/frappe-bench/apps/frappe/frappe/utils/scheduler.py", line 237, in is_scheduler_disabled
    return not frappe.utils.cint(frappe.db.get_single_value("System Settings", "enable_scheduler"))
  File "/home/attiq/frappe-bench/apps/frappe/frappe/database/database.py", line 553, in get_single_value
    `tabSingles` where `doctype`=%s and `field`=%s""", (doctype, fieldname))
  File "/home/attiq/frappe-bench/apps/frappe/frappe/database/database.py", line 122, in sql
    self.connect()
  File "/home/attiq/frappe-bench/apps/frappe/frappe/database/database.py", line 75, in connect
    self._conn = self.get_connection()
  File "/home/attiq/frappe-bench/apps/frappe/frappe/database/mariadb/database.py", line 90, in get_connection
    local_infile = frappe.conf.local_infile)
  File "/home/attiq/frappe-bench/env/lib/python3.6/site-packages/pymysql/__init__.py", line 94, in Connect
    return Connection(*args, **kwargs)
  File "/home/attiq/frappe-bench/env/lib/python3.6/site-packages/pymysql/connections.py", line 325, in __init__
    self.connect()
  File "/home/attiq/frappe-bench/env/lib/python3.6/site-packages/pymysql/connections.py", line 630, in connect
    raise exc
pymysql.err.OperationalError: (2003, "Can't connect to MySQL server on '192.168.2.219' (timed out)")

[ERROR] 2021-11-30 11:28:07,120 | /home/attiq/frappe-bench/apps/frappe/frappe/utils/scheduler.py:
Site: local.nerp
Exception in Enqueue Events for Site local.nerp
Traceback (most recent call last):
  File "/home/attiq/frappe-bench/env/lib/python3.6/site-packages/pymysql/connections.py", line 583, in connect
    **kwargs)
  File "/usr/lib/python3.6/socket.py", line 724, in create_connection
    raise err
  File "/usr/lib/python3.6/socket.py", line 713, in create_connection
    sock.connect(sa)
socket.timeout: timed out

During handling of the above exception, another exception occurred:

Traceback (most recent call last):
  File "/home/attiq/frappe-bench/apps/frappe/frappe/utils/scheduler.py", line 81, in enqueue_events_for_site
    if is_scheduler_inactive():
  File "/home/attiq/frappe-bench/apps/frappe/frappe/utils/scheduler.py", line 228, in is_scheduler_inactive
    if is_scheduler_disabled():
  File "/home/attiq/frappe-bench/apps/frappe/frappe/utils/scheduler.py", line 237, in is_scheduler_disabled
    return not frappe.utils.cint(frappe.db.get_single_value("System Settings", "enable_scheduler"))
  File "/home/attiq/frappe-bench/apps/frappe/frappe/database/database.py", line 553, in get_single_value
    `tabSingles` where `doctype`=%s and `field`=%s""", (doctype, fieldname))
  File "/home/attiq/frappe-bench/apps/frappe/frappe/database/database.py", line 122, in sql
    self.connect()
  File "/home/attiq/frappe-bench/apps/frappe/frappe/database/database.py", line 75, in connect
    self._conn = self.get_connection()
  File "/home/attiq/frappe-bench/apps/frappe/frappe/database/mariadb/database.py", line 90, in get_connection
    local_infile = frappe.conf.local_infile)
  File "/home/attiq/frappe-bench/env/lib/python3.6/site-packages/pymysql/__init__.py", line 94, in Connect
    return Connection(*args, **kwargs)
  File "/home/attiq/frappe-bench/env/lib/python3.6/site-packages/pymysql/connections.py", line 325, in __init__
    self.connect()
  File "/home/attiq/frappe-bench/env/lib/python3.6/site-packages/pymysql/connections.py", line 630, in connect
    raise exc
pymysql.err.OperationalError: (2003, "Can't connect to MySQL server on '192.168.2.219' (timed out)")

[ERROR] 2021-11-30 11:29:17,200 | /home/attiq/frappe-bench/apps/frappe/frappe/utils/scheduler.py:
Site: erp.sample
Exception in Enqueue Events for Site erp.sample
Traceback (most recent call last):
  File "/home/attiq/frappe-bench/env/lib/python3.6/site-packages/pymysql/connections.py", line 583, in connect
    **kwargs)
  File "/usr/lib/python3.6/socket.py", line 724, in create_connection
    raise err
  File "/usr/lib/python3.6/socket.py", line 713, in create_connection
    sock.connect(sa)
socket.timeout: timed out

During handling of the above exception, another exception occurred:

Traceback (most recent call last):
  File "/home/attiq/frappe-bench/apps/frappe/frappe/utils/scheduler.py", line 81, in enqueue_events_for_site
    if is_scheduler_inactive():
  File "/home/attiq/frappe-bench/apps/frappe/frappe/utils/scheduler.py", line 228, in is_scheduler_inactive
    if is_scheduler_disabled():
  File "/home/attiq/frappe-bench/apps/frappe/frappe/utils/scheduler.py", line 237, in is_scheduler_disabled
    return not frappe.utils.cint(frappe.db.get_single_value("System Settings", "enable_scheduler"))
  File "/home/attiq/frappe-bench/apps/frappe/frappe/database/database.py", line 553, in get_single_value
    `tabSingles` where `doctype`=%s and `field`=%s""", (doctype, fieldname))
  File "/home/attiq/frappe-bench/apps/frappe/frappe/database/database.py", line 122, in sql
    self.connect()
  File "/home/attiq/frappe-bench/apps/frappe/frappe/database/database.py", line 75, in connect
    self._conn = self.get_connection()
  File "/home/attiq/frappe-bench/apps/frappe/frappe/database/mariadb/database.py", line 90, in get_connection
    local_infile = frappe.conf.local_infile)
  File "/home/attiq/frappe-bench/env/lib/python3.6/site-packages/pymysql/__init__.py", line 94, in Connect
    return Connection(*args, **kwargs)
  File "/home/attiq/frappe-bench/env/lib/python3.6/site-packages/pymysql/connections.py", line 325, in __init__
    self.connect()
  File "/home/attiq/frappe-bench/env/lib/python3.6/site-packages/pymysql/connections.py", line 630, in connect
    raise exc
pymysql.err.OperationalError: (2003, "Can't connect to MySQL server on '192.168.2.219' (timed out)")

[ERROR] 2021-11-30 11:29:27,212 | /home/attiq/frappe-bench/apps/frappe/frappe/utils/scheduler.py:
Site: foo.bar
Exception in Enqueue Events for Site foo.bar
Traceback (most recent call last):
  File "/home/attiq/frappe-bench/env/lib/python3.6/site-packages/pymysql/connections.py", line 583, in connect
    **kwargs)
  File "/usr/lib/python3.6/socket.py", line 724, in create_connection
    raise err
  File "/usr/lib/python3.6/socket.py", line 713, in create_connection
    sock.connect(sa)
socket.timeout: timed out

During handling of the above exception, another exception occurred:

Traceback (most recent call last):
  File "/home/attiq/frappe-bench/apps/frappe/frappe/utils/scheduler.py", line 81, in enqueue_events_for_site
    if is_scheduler_inactive():
  File "/home/attiq/frappe-bench/apps/frappe/frappe/utils/scheduler.py", line 228, in is_scheduler_inactive
    if is_scheduler_disabled():
  File "/home/attiq/frappe-bench/apps/frappe/frappe/utils/scheduler.py", line 237, in is_scheduler_disabled
    return not frappe.utils.cint(frappe.db.get_single_value("System Settings", "enable_scheduler"))
  File "/home/attiq/frappe-bench/apps/frappe/frappe/database/database.py", line 553, in get_single_value
    `tabSingles` where `doctype`=%s and `field`=%s""", (doctype, fieldname))
  File "/home/attiq/frappe-bench/apps/frappe/frappe/database/database.py", line 122, in sql
    self.connect()
  File "/home/attiq/frappe-bench/apps/frappe/frappe/database/database.py", line 75, in connect
    self._conn = self.get_connection()
  File "/home/attiq/frappe-bench/apps/frappe/frappe/database/mariadb/database.py", line 90, in get_connection
    local_infile = frappe.conf.local_infile)
  File "/home/attiq/frappe-bench/env/lib/python3.6/site-packages/pymysql/__init__.py", line 94, in Connect
    return Connection(*args, **kwargs)
  File "/home/attiq/frappe-bench/env/lib/python3.6/site-packages/pymysql/connections.py", line 325, in __init__
    self.connect()
  File "/home/attiq/frappe-bench/env/lib/python3.6/site-packages/pymysql/connections.py", line 630, in connect
    raise exc
pymysql.err.OperationalError: (2003, "Can't connect to MySQL server on '192.168.2.219' (timed out)")

[DEBUG] 2021-11-30 11:29:27,494 | /home/attiq/frappe-bench/apps/frappe/frappe/utils/scheduler.py:
Site: gourmet.nerp
Queued events for site gourmet.nerp
[ERROR] 2021-11-30 11:29:37,505 | /home/attiq/frappe-bench/apps/frappe/frappe/utils/scheduler.py:
Site: gourmet.nrp
Exception in Enqueue Events for Site gourmet.nrp
Traceback (most recent call last):
  File "/home/attiq/frappe-bench/env/lib/python3.6/site-packages/pymysql/connections.py", line 583, in connect
    **kwargs)
  File "/usr/lib/python3.6/socket.py", line 724, in create_connection
    raise err
  File "/usr/lib/python3.6/socket.py", line 713, in create_connection
    sock.connect(sa)
socket.timeout: timed out

During handling of the above exception, another exception occurred:

Traceback (most recent call last):
  File "/home/attiq/frappe-bench/apps/frappe/frappe/utils/scheduler.py", line 81, in enqueue_events_for_site
    if is_scheduler_inactive():
  File "/home/attiq/frappe-bench/apps/frappe/frappe/utils/scheduler.py", line 228, in is_scheduler_inactive
    if is_scheduler_disabled():
  File "/home/attiq/frappe-bench/apps/frappe/frappe/utils/scheduler.py", line 237, in is_scheduler_disabled
    return not frappe.utils.cint(frappe.db.get_single_value("System Settings", "enable_scheduler"))
  File "/home/attiq/frappe-bench/apps/frappe/frappe/database/database.py", line 553, in get_single_value
    `tabSingles` where `doctype`=%s and `field`=%s""", (doctype, fieldname))
  File "/home/attiq/frappe-bench/apps/frappe/frappe/database/database.py", line 122, in sql
    self.connect()
  File "/home/attiq/frappe-bench/apps/frappe/frappe/database/database.py", line 75, in connect
    self._conn = self.get_connection()
  File "/home/attiq/frappe-bench/apps/frappe/frappe/database/mariadb/database.py", line 90, in get_connection
    local_infile = frappe.conf.local_infile)
  File "/home/attiq/frappe-bench/env/lib/python3.6/site-packages/pymysql/__init__.py", line 94, in Connect
    return Connection(*args, **kwargs)
  File "/home/attiq/frappe-bench/env/lib/python3.6/site-packages/pymysql/connections.py", line 325, in __init__
    self.connect()
  File "/home/attiq/frappe-bench/env/lib/python3.6/site-packages/pymysql/connections.py", line 630, in connect
    raise exc
pymysql.err.OperationalError: (2003, "Can't connect to MySQL server on '192.168.2.219' (timed out)")

[ERROR] 2021-11-30 11:29:47,517 | /home/attiq/frappe-bench/apps/frappe/frappe/utils/scheduler.py:
Site: local.nerp
Exception in Enqueue Events for Site local.nerp
Traceback (most recent call last):
  File "/home/attiq/frappe-bench/env/lib/python3.6/site-packages/pymysql/connections.py", line 583, in connect
    **kwargs)
  File "/usr/lib/python3.6/socket.py", line 724, in create_connection
    raise err
  File "/usr/lib/python3.6/socket.py", line 713, in create_connection
    sock.connect(sa)
socket.timeout: timed out

During handling of the above exception, another exception occurred:

Traceback (most recent call last):
  File "/home/attiq/frappe-bench/apps/frappe/frappe/utils/scheduler.py", line 81, in enqueue_events_for_site
    if is_scheduler_inactive():
  File "/home/attiq/frappe-bench/apps/frappe/frappe/utils/scheduler.py", line 228, in is_scheduler_inactive
    if is_scheduler_disabled():
  File "/home/attiq/frappe-bench/apps/frappe/frappe/utils/scheduler.py", line 237, in is_scheduler_disabled
    return not frappe.utils.cint(frappe.db.get_single_value("System Settings", "enable_scheduler"))
  File "/home/attiq/frappe-bench/apps/frappe/frappe/database/database.py", line 553, in get_single_value
    `tabSingles` where `doctype`=%s and `field`=%s""", (doctype, fieldname))
  File "/home/attiq/frappe-bench/apps/frappe/frappe/database/database.py", line 122, in sql
    self.connect()
  File "/home/attiq/frappe-bench/apps/frappe/frappe/database/database.py", line 75, in connect
    self._conn = self.get_connection()
  File "/home/attiq/frappe-bench/apps/frappe/frappe/database/mariadb/database.py", line 90, in get_connection
    local_infile = frappe.conf.local_infile)
  File "/home/attiq/frappe-bench/env/lib/python3.6/site-packages/pymysql/__init__.py", line 94, in Connect
    return Connection(*args, **kwargs)
  File "/home/attiq/frappe-bench/env/lib/python3.6/site-packages/pymysql/connections.py", line 325, in __init__
    self.connect()
  File "/home/attiq/frappe-bench/env/lib/python3.6/site-packages/pymysql/connections.py", line 630, in connect
    raise exc
pymysql.err.OperationalError: (2003, "Can't connect to MySQL server on '192.168.2.219' (timed out)")

[ERROR] 2021-11-30 11:30:57,600 | /home/attiq/frappe-bench/apps/frappe/frappe/utils/scheduler.py:
Site: erp.sample
Exception in Enqueue Events for Site erp.sample
Traceback (most recent call last):
  File "/home/attiq/frappe-bench/env/lib/python3.6/site-packages/pymysql/connections.py", line 583, in connect
    **kwargs)
  File "/usr/lib/python3.6/socket.py", line 724, in create_connection
    raise err
  File "/usr/lib/python3.6/socket.py", line 713, in create_connection
    sock.connect(sa)
socket.timeout: timed out

During handling of the above exception, another exception occurred:

Traceback (most recent call last):
  File "/home/attiq/frappe-bench/apps/frappe/frappe/utils/scheduler.py", line 81, in enqueue_events_for_site
    if is_scheduler_inactive():
  File "/home/attiq/frappe-bench/apps/frappe/frappe/utils/scheduler.py", line 228, in is_scheduler_inactive
    if is_scheduler_disabled():
  File "/home/attiq/frappe-bench/apps/frappe/frappe/utils/scheduler.py", line 237, in is_scheduler_disabled
    return not frappe.utils.cint(frappe.db.get_single_value("System Settings", "enable_scheduler"))
  File "/home/attiq/frappe-bench/apps/frappe/frappe/database/database.py", line 553, in get_single_value
    `tabSingles` where `doctype`=%s and `field`=%s""", (doctype, fieldname))
  File "/home/attiq/frappe-bench/apps/frappe/frappe/database/database.py", line 122, in sql
    self.connect()
  File "/home/attiq/frappe-bench/apps/frappe/frappe/database/database.py", line 75, in connect
    self._conn = self.get_connection()
  File "/home/attiq/frappe-bench/apps/frappe/frappe/database/mariadb/database.py", line 90, in get_connection
    local_infile = frappe.conf.local_infile)
  File "/home/attiq/frappe-bench/env/lib/python3.6/site-packages/pymysql/__init__.py", line 94, in Connect
    return Connection(*args, **kwargs)
  File "/home/attiq/frappe-bench/env/lib/python3.6/site-packages/pymysql/connections.py", line 325, in __init__
    self.connect()
  File "/home/attiq/frappe-bench/env/lib/python3.6/site-packages/pymysql/connections.py", line 630, in connect
    raise exc
pymysql.err.OperationalError: (2003, "Can't connect to MySQL server on '192.168.2.219' (timed out)")

[ERROR] 2021-11-30 11:31:07,612 | /home/attiq/frappe-bench/apps/frappe/frappe/utils/scheduler.py:
Site: foo.bar
Exception in Enqueue Events for Site foo.bar
Traceback (most recent call last):
  File "/home/attiq/frappe-bench/env/lib/python3.6/site-packages/pymysql/connections.py", line 583, in connect
    **kwargs)
  File "/usr/lib/python3.6/socket.py", line 724, in create_connection
    raise err
  File "/usr/lib/python3.6/socket.py", line 713, in create_connection
    sock.connect(sa)
socket.timeout: timed out

During handling of the above exception, another exception occurred:

Traceback (most recent call last):
  File "/home/attiq/frappe-bench/apps/frappe/frappe/utils/scheduler.py", line 81, in enqueue_events_for_site
    if is_scheduler_inactive():
  File "/home/attiq/frappe-bench/apps/frappe/frappe/utils/scheduler.py", line 228, in is_scheduler_inactive
    if is_scheduler_disabled():
  File "/home/attiq/frappe-bench/apps/frappe/frappe/utils/scheduler.py", line 237, in is_scheduler_disabled
    return not frappe.utils.cint(frappe.db.get_single_value("System Settings", "enable_scheduler"))
  File "/home/attiq/frappe-bench/apps/frappe/frappe/database/database.py", line 553, in get_single_value
    `tabSingles` where `doctype`=%s and `field`=%s""", (doctype, fieldname))
  File "/home/attiq/frappe-bench/apps/frappe/frappe/database/database.py", line 122, in sql
    self.connect()
  File "/home/attiq/frappe-bench/apps/frappe/frappe/database/database.py", line 75, in connect
    self._conn = self.get_connection()
  File "/home/attiq/frappe-bench/apps/frappe/frappe/database/mariadb/database.py", line 90, in get_connection
    local_infile = frappe.conf.local_infile)
  File "/home/attiq/frappe-bench/env/lib/python3.6/site-packages/pymysql/__init__.py", line 94, in Connect
    return Connection(*args, **kwargs)
  File "/home/attiq/frappe-bench/env/lib/python3.6/site-packages/pymysql/connections.py", line 325, in __init__
    self.connect()
  File "/home/attiq/frappe-bench/env/lib/python3.6/site-packages/pymysql/connections.py", line 630, in connect
    raise exc
pymysql.err.OperationalError: (2003, "Can't connect to MySQL server on '192.168.2.219' (timed out)")

[DEBUG] 2021-11-30 11:31:07,661 | /home/attiq/frappe-bench/apps/frappe/frappe/utils/scheduler.py:
Site: gourmet.nerp
Queued events for site gourmet.nerp
[ERROR] 2021-11-30 11:31:17,672 | /home/attiq/frappe-bench/apps/frappe/frappe/utils/scheduler.py:
Site: gourmet.nrp
Exception in Enqueue Events for Site gourmet.nrp
Traceback (most recent call last):
  File "/home/attiq/frappe-bench/env/lib/python3.6/site-packages/pymysql/connections.py", line 583, in connect
    **kwargs)
  File "/usr/lib/python3.6/socket.py", line 724, in create_connection
    raise err
  File "/usr/lib/python3.6/socket.py", line 713, in create_connection
    sock.connect(sa)
socket.timeout: timed out

During handling of the above exception, another exception occurred:

Traceback (most recent call last):
  File "/home/attiq/frappe-bench/apps/frappe/frappe/utils/scheduler.py", line 81, in enqueue_events_for_site
    if is_scheduler_inactive():
  File "/home/attiq/frappe-bench/apps/frappe/frappe/utils/scheduler.py", line 228, in is_scheduler_inactive
    if is_scheduler_disabled():
  File "/home/attiq/frappe-bench/apps/frappe/frappe/utils/scheduler.py", line 237, in is_scheduler_disabled
    return not frappe.utils.cint(frappe.db.get_single_value("System Settings", "enable_scheduler"))
  File "/home/attiq/frappe-bench/apps/frappe/frappe/database/database.py", line 553, in get_single_value
    `tabSingles` where `doctype`=%s and `field`=%s""", (doctype, fieldname))
  File "/home/attiq/frappe-bench/apps/frappe/frappe/database/database.py", line 122, in sql
    self.connect()
  File "/home/attiq/frappe-bench/apps/frappe/frappe/database/database.py", line 75, in connect
    self._conn = self.get_connection()
  File "/home/attiq/frappe-bench/apps/frappe/frappe/database/mariadb/database.py", line 90, in get_connection
    local_infile = frappe.conf.local_infile)
  File "/home/attiq/frappe-bench/env/lib/python3.6/site-packages/pymysql/__init__.py", line 94, in Connect
    return Connection(*args, **kwargs)
  File "/home/attiq/frappe-bench/env/lib/python3.6/site-packages/pymysql/connections.py", line 325, in __init__
    self.connect()
  File "/home/attiq/frappe-bench/env/lib/python3.6/site-packages/pymysql/connections.py", line 630, in connect
    raise exc
pymysql.err.OperationalError: (2003, "Can't connect to MySQL server on '192.168.2.219' (timed out)")

[ERROR] 2021-11-30 11:31:27,680 | /home/attiq/frappe-bench/apps/frappe/frappe/utils/scheduler.py:
Site: local.nerp
Exception in Enqueue Events for Site local.nerp
Traceback (most recent call last):
  File "/home/attiq/frappe-bench/env/lib/python3.6/site-packages/pymysql/connections.py", line 583, in connect
    **kwargs)
  File "/usr/lib/python3.6/socket.py", line 724, in create_connection
    raise err
  File "/usr/lib/python3.6/socket.py", line 713, in create_connection
    sock.connect(sa)
socket.timeout: timed out

During handling of the above exception, another exception occurred:

Traceback (most recent call last):
  File "/home/attiq/frappe-bench/apps/frappe/frappe/utils/scheduler.py", line 81, in enqueue_events_for_site
    if is_scheduler_inactive():
  File "/home/attiq/frappe-bench/apps/frappe/frappe/utils/scheduler.py", line 228, in is_scheduler_inactive
    if is_scheduler_disabled():
  File "/home/attiq/frappe-bench/apps/frappe/frappe/utils/scheduler.py", line 237, in is_scheduler_disabled
    return not frappe.utils.cint(frappe.db.get_single_value("System Settings", "enable_scheduler"))
  File "/home/attiq/frappe-bench/apps/frappe/frappe/database/database.py", line 553, in get_single_value
    `tabSingles` where `doctype`=%s and `field`=%s""", (doctype, fieldname))
  File "/home/attiq/frappe-bench/apps/frappe/frappe/database/database.py", line 122, in sql
    self.connect()
  File "/home/attiq/frappe-bench/apps/frappe/frappe/database/database.py", line 75, in connect
    self._conn = self.get_connection()
  File "/home/attiq/frappe-bench/apps/frappe/frappe/database/mariadb/database.py", line 90, in get_connection
    local_infile = frappe.conf.local_infile)
  File "/home/attiq/frappe-bench/env/lib/python3.6/site-packages/pymysql/__init__.py", line 94, in Connect
    return Connection(*args, **kwargs)
  File "/home/attiq/frappe-bench/env/lib/python3.6/site-packages/pymysql/connections.py", line 325, in __init__
    self.connect()
  File "/home/attiq/frappe-bench/env/lib/python3.6/site-packages/pymysql/connections.py", line 630, in connect
    raise exc
pymysql.err.OperationalError: (2003, "Can't connect to MySQL server on '192.168.2.219' (timed out)")

[ERROR] 2021-11-30 11:32:37,762 | /home/attiq/frappe-bench/apps/frappe/frappe/utils/scheduler.py:
Site: erp.sample
Exception in Enqueue Events for Site erp.sample
Traceback (most recent call last):
  File "/home/attiq/frappe-bench/env/lib/python3.6/site-packages/pymysql/connections.py", line 583, in connect
    **kwargs)
  File "/usr/lib/python3.6/socket.py", line 724, in create_connection
    raise err
  File "/usr/lib/python3.6/socket.py", line 713, in create_connection
    sock.connect(sa)
socket.timeout: timed out

During handling of the above exception, another exception occurred:

Traceback (most recent call last):
  File "/home/attiq/frappe-bench/apps/frappe/frappe/utils/scheduler.py", line 81, in enqueue_events_for_site
    if is_scheduler_inactive():
  File "/home/attiq/frappe-bench/apps/frappe/frappe/utils/scheduler.py", line 228, in is_scheduler_inactive
    if is_scheduler_disabled():
  File "/home/attiq/frappe-bench/apps/frappe/frappe/utils/scheduler.py", line 237, in is_scheduler_disabled
    return not frappe.utils.cint(frappe.db.get_single_value("System Settings", "enable_scheduler"))
  File "/home/attiq/frappe-bench/apps/frappe/frappe/database/database.py", line 553, in get_single_value
    `tabSingles` where `doctype`=%s and `field`=%s""", (doctype, fieldname))
  File "/home/attiq/frappe-bench/apps/frappe/frappe/database/database.py", line 122, in sql
    self.connect()
  File "/home/attiq/frappe-bench/apps/frappe/frappe/database/database.py", line 75, in connect
    self._conn = self.get_connection()
  File "/home/attiq/frappe-bench/apps/frappe/frappe/database/mariadb/database.py", line 90, in get_connection
    local_infile = frappe.conf.local_infile)
  File "/home/attiq/frappe-bench/env/lib/python3.6/site-packages/pymysql/__init__.py", line 94, in Connect
    return Connection(*args, **kwargs)
  File "/home/attiq/frappe-bench/env/lib/python3.6/site-packages/pymysql/connections.py", line 325, in __init__
    self.connect()
  File "/home/attiq/frappe-bench/env/lib/python3.6/site-packages/pymysql/connections.py", line 630, in connect
    raise exc
pymysql.err.OperationalError: (2003, "Can't connect to MySQL server on '192.168.2.219' (timed out)")

[ERROR] 2021-11-30 11:32:47,765 | /home/attiq/frappe-bench/apps/frappe/frappe/utils/scheduler.py:
Site: foo.bar
Exception in Enqueue Events for Site foo.bar
Traceback (most recent call last):
  File "/home/attiq/frappe-bench/env/lib/python3.6/site-packages/pymysql/connections.py", line 583, in connect
    **kwargs)
  File "/usr/lib/python3.6/socket.py", line 724, in create_connection
    raise err
  File "/usr/lib/python3.6/socket.py", line 713, in create_connection
    sock.connect(sa)
socket.timeout: timed out

During handling of the above exception, another exception occurred:

Traceback (most recent call last):
  File "/home/attiq/frappe-bench/apps/frappe/frappe/utils/scheduler.py", line 81, in enqueue_events_for_site
    if is_scheduler_inactive():
  File "/home/attiq/frappe-bench/apps/frappe/frappe/utils/scheduler.py", line 228, in is_scheduler_inactive
    if is_scheduler_disabled():
  File "/home/attiq/frappe-bench/apps/frappe/frappe/utils/scheduler.py", line 237, in is_scheduler_disabled
    return not frappe.utils.cint(frappe.db.get_single_value("System Settings", "enable_scheduler"))
  File "/home/attiq/frappe-bench/apps/frappe/frappe/database/database.py", line 553, in get_single_value
    `tabSingles` where `doctype`=%s and `field`=%s""", (doctype, fieldname))
  File "/home/attiq/frappe-bench/apps/frappe/frappe/database/database.py", line 122, in sql
    self.connect()
  File "/home/attiq/frappe-bench/apps/frappe/frappe/database/database.py", line 75, in connect
    self._conn = self.get_connection()
  File "/home/attiq/frappe-bench/apps/frappe/frappe/database/mariadb/database.py", line 90, in get_connection
    local_infile = frappe.conf.local_infile)
  File "/home/attiq/frappe-bench/env/lib/python3.6/site-packages/pymysql/__init__.py", line 94, in Connect
    return Connection(*args, **kwargs)
  File "/home/attiq/frappe-bench/env/lib/python3.6/site-packages/pymysql/connections.py", line 325, in __init__
    self.connect()
  File "/home/attiq/frappe-bench/env/lib/python3.6/site-packages/pymysql/connections.py", line 630, in connect
    raise exc
pymysql.err.OperationalError: (2003, "Can't connect to MySQL server on '192.168.2.219' (timed out)")

[DEBUG] 2021-11-30 11:32:48,298 | /home/attiq/frappe-bench/apps/frappe/frappe/utils/scheduler.py:
Site: gourmet.nerp
Queued events for site gourmet.nerp
[ERROR] 2021-11-30 11:32:58,308 | /home/attiq/frappe-bench/apps/frappe/frappe/utils/scheduler.py:
Site: gourmet.nrp
Exception in Enqueue Events for Site gourmet.nrp
Traceback (most recent call last):
  File "/home/attiq/frappe-bench/env/lib/python3.6/site-packages/pymysql/connections.py", line 583, in connect
    **kwargs)
  File "/usr/lib/python3.6/socket.py", line 724, in create_connection
    raise err
  File "/usr/lib/python3.6/socket.py", line 713, in create_connection
    sock.connect(sa)
socket.timeout: timed out

During handling of the above exception, another exception occurred:

Traceback (most recent call last):
  File "/home/attiq/frappe-bench/apps/frappe/frappe/utils/scheduler.py", line 81, in enqueue_events_for_site
    if is_scheduler_inactive():
  File "/home/attiq/frappe-bench/apps/frappe/frappe/utils/scheduler.py", line 228, in is_scheduler_inactive
    if is_scheduler_disabled():
  File "/home/attiq/frappe-bench/apps/frappe/frappe/utils/scheduler.py", line 237, in is_scheduler_disabled
    return not frappe.utils.cint(frappe.db.get_single_value("System Settings", "enable_scheduler"))
  File "/home/attiq/frappe-bench/apps/frappe/frappe/database/database.py", line 553, in get_single_value
    `tabSingles` where `doctype`=%s and `field`=%s""", (doctype, fieldname))
  File "/home/attiq/frappe-bench/apps/frappe/frappe/database/database.py", line 122, in sql
    self.connect()
  File "/home/attiq/frappe-bench/apps/frappe/frappe/database/database.py", line 75, in connect
    self._conn = self.get_connection()
  File "/home/attiq/frappe-bench/apps/frappe/frappe/database/mariadb/database.py", line 90, in get_connection
    local_infile = frappe.conf.local_infile)
  File "/home/attiq/frappe-bench/env/lib/python3.6/site-packages/pymysql/__init__.py", line 94, in Connect
    return Connection(*args, **kwargs)
  File "/home/attiq/frappe-bench/env/lib/python3.6/site-packages/pymysql/connections.py", line 325, in __init__
    self.connect()
  File "/home/attiq/frappe-bench/env/lib/python3.6/site-packages/pymysql/connections.py", line 630, in connect
    raise exc
pymysql.err.OperationalError: (2003, "Can't connect to MySQL server on '192.168.2.219' (timed out)")

[ERROR] 2021-11-30 11:33:08,316 | /home/attiq/frappe-bench/apps/frappe/frappe/utils/scheduler.py:
Site: local.nerp
Exception in Enqueue Events for Site local.nerp
Traceback (most recent call last):
  File "/home/attiq/frappe-bench/env/lib/python3.6/site-packages/pymysql/connections.py", line 583, in connect
    **kwargs)
  File "/usr/lib/python3.6/socket.py", line 724, in create_connection
    raise err
  File "/usr/lib/python3.6/socket.py", line 713, in create_connection
    sock.connect(sa)
socket.timeout: timed out

During handling of the above exception, another exception occurred:

Traceback (most recent call last):
  File "/home/attiq/frappe-bench/apps/frappe/frappe/utils/scheduler.py", line 81, in enqueue_events_for_site
    if is_scheduler_inactive():
  File "/home/attiq/frappe-bench/apps/frappe/frappe/utils/scheduler.py", line 228, in is_scheduler_inactive
    if is_scheduler_disabled():
  File "/home/attiq/frappe-bench/apps/frappe/frappe/utils/scheduler.py", line 237, in is_scheduler_disabled
    return not frappe.utils.cint(frappe.db.get_single_value("System Settings", "enable_scheduler"))
  File "/home/attiq/frappe-bench/apps/frappe/frappe/database/database.py", line 553, in get_single_value
    `tabSingles` where `doctype`=%s and `field`=%s""", (doctype, fieldname))
  File "/home/attiq/frappe-bench/apps/frappe/frappe/database/database.py", line 122, in sql
    self.connect()
  File "/home/attiq/frappe-bench/apps/frappe/frappe/database/database.py", line 75, in connect
    self._conn = self.get_connection()
  File "/home/attiq/frappe-bench/apps/frappe/frappe/database/mariadb/database.py", line 90, in get_connection
    local_infile = frappe.conf.local_infile)
  File "/home/attiq/frappe-bench/env/lib/python3.6/site-packages/pymysql/__init__.py", line 94, in Connect
    return Connection(*args, **kwargs)
  File "/home/attiq/frappe-bench/env/lib/python3.6/site-packages/pymysql/connections.py", line 325, in __init__
    self.connect()
  File "/home/attiq/frappe-bench/env/lib/python3.6/site-packages/pymysql/connections.py", line 630, in connect
    raise exc
pymysql.err.OperationalError: (2003, "Can't connect to MySQL server on '192.168.2.219' (timed out)")

[ERROR] 2021-11-30 11:34:18,396 | /home/attiq/frappe-bench/apps/frappe/frappe/utils/scheduler.py:
Site: erp.sample
Exception in Enqueue Events for Site erp.sample
Traceback (most recent call last):
  File "/home/attiq/frappe-bench/env/lib/python3.6/site-packages/pymysql/connections.py", line 583, in connect
    **kwargs)
  File "/usr/lib/python3.6/socket.py", line 724, in create_connection
    raise err
  File "/usr/lib/python3.6/socket.py", line 713, in create_connection
    sock.connect(sa)
socket.timeout: timed out

During handling of the above exception, another exception occurred:

Traceback (most recent call last):
  File "/home/attiq/frappe-bench/apps/frappe/frappe/utils/scheduler.py", line 81, in enqueue_events_for_site
    if is_scheduler_inactive():
  File "/home/attiq/frappe-bench/apps/frappe/frappe/utils/scheduler.py", line 228, in is_scheduler_inactive
    if is_scheduler_disabled():
  File "/home/attiq/frappe-bench/apps/frappe/frappe/utils/scheduler.py", line 237, in is_scheduler_disabled
    return not frappe.utils.cint(frappe.db.get_single_value("System Settings", "enable_scheduler"))
  File "/home/attiq/frappe-bench/apps/frappe/frappe/database/database.py", line 553, in get_single_value
    `tabSingles` where `doctype`=%s and `field`=%s""", (doctype, fieldname))
  File "/home/attiq/frappe-bench/apps/frappe/frappe/database/database.py", line 122, in sql
    self.connect()
  File "/home/attiq/frappe-bench/apps/frappe/frappe/database/database.py", line 75, in connect
    self._conn = self.get_connection()
  File "/home/attiq/frappe-bench/apps/frappe/frappe/database/mariadb/database.py", line 90, in get_connection
    local_infile = frappe.conf.local_infile)
  File "/home/attiq/frappe-bench/env/lib/python3.6/site-packages/pymysql/__init__.py", line 94, in Connect
    return Connection(*args, **kwargs)
  File "/home/attiq/frappe-bench/env/lib/python3.6/site-packages/pymysql/connections.py", line 325, in __init__
    self.connect()
  File "/home/attiq/frappe-bench/env/lib/python3.6/site-packages/pymysql/connections.py", line 630, in connect
    raise exc
pymysql.err.OperationalError: (2003, "Can't connect to MySQL server on '192.168.2.219' (timed out)")

[ERROR] 2021-11-30 11:34:28,408 | /home/attiq/frappe-bench/apps/frappe/frappe/utils/scheduler.py:
Site: foo.bar
Exception in Enqueue Events for Site foo.bar
Traceback (most recent call last):
  File "/home/attiq/frappe-bench/env/lib/python3.6/site-packages/pymysql/connections.py", line 583, in connect
    **kwargs)
  File "/usr/lib/python3.6/socket.py", line 724, in create_connection
    raise err
  File "/usr/lib/python3.6/socket.py", line 713, in create_connection
    sock.connect(sa)
socket.timeout: timed out

During handling of the above exception, another exception occurred:

Traceback (most recent call last):
  File "/home/attiq/frappe-bench/apps/frappe/frappe/utils/scheduler.py", line 81, in enqueue_events_for_site
    if is_scheduler_inactive():
  File "/home/attiq/frappe-bench/apps/frappe/frappe/utils/scheduler.py", line 228, in is_scheduler_inactive
    if is_scheduler_disabled():
  File "/home/attiq/frappe-bench/apps/frappe/frappe/utils/scheduler.py", line 237, in is_scheduler_disabled
    return not frappe.utils.cint(frappe.db.get_single_value("System Settings", "enable_scheduler"))
  File "/home/attiq/frappe-bench/apps/frappe/frappe/database/database.py", line 553, in get_single_value
    `tabSingles` where `doctype`=%s and `field`=%s""", (doctype, fieldname))
  File "/home/attiq/frappe-bench/apps/frappe/frappe/database/database.py", line 122, in sql
    self.connect()
  File "/home/attiq/frappe-bench/apps/frappe/frappe/database/database.py", line 75, in connect
    self._conn = self.get_connection()
  File "/home/attiq/frappe-bench/apps/frappe/frappe/database/mariadb/database.py", line 90, in get_connection
    local_infile = frappe.conf.local_infile)
  File "/home/attiq/frappe-bench/env/lib/python3.6/site-packages/pymysql/__init__.py", line 94, in Connect
    return Connection(*args, **kwargs)
  File "/home/attiq/frappe-bench/env/lib/python3.6/site-packages/pymysql/connections.py", line 325, in __init__
    self.connect()
  File "/home/attiq/frappe-bench/env/lib/python3.6/site-packages/pymysql/connections.py", line 630, in connect
    raise exc
pymysql.err.OperationalError: (2003, "Can't connect to MySQL server on '192.168.2.219' (timed out)")

[DEBUG] 2021-11-30 11:34:28,462 | /home/attiq/frappe-bench/apps/frappe/frappe/utils/scheduler.py:
Site: gourmet.nerp
Queued events for site gourmet.nerp
[ERROR] 2021-11-30 11:34:38,473 | /home/attiq/frappe-bench/apps/frappe/frappe/utils/scheduler.py:
Site: gourmet.nrp
Exception in Enqueue Events for Site gourmet.nrp
Traceback (most recent call last):
  File "/home/attiq/frappe-bench/env/lib/python3.6/site-packages/pymysql/connections.py", line 583, in connect
    **kwargs)
  File "/usr/lib/python3.6/socket.py", line 724, in create_connection
    raise err
  File "/usr/lib/python3.6/socket.py", line 713, in create_connection
    sock.connect(sa)
socket.timeout: timed out

During handling of the above exception, another exception occurred:

Traceback (most recent call last):
  File "/home/attiq/frappe-bench/apps/frappe/frappe/utils/scheduler.py", line 81, in enqueue_events_for_site
    if is_scheduler_inactive():
  File "/home/attiq/frappe-bench/apps/frappe/frappe/utils/scheduler.py", line 228, in is_scheduler_inactive
    if is_scheduler_disabled():
  File "/home/attiq/frappe-bench/apps/frappe/frappe/utils/scheduler.py", line 237, in is_scheduler_disabled
    return not frappe.utils.cint(frappe.db.get_single_value("System Settings", "enable_scheduler"))
  File "/home/attiq/frappe-bench/apps/frappe/frappe/database/database.py", line 553, in get_single_value
    `tabSingles` where `doctype`=%s and `field`=%s""", (doctype, fieldname))
  File "/home/attiq/frappe-bench/apps/frappe/frappe/database/database.py", line 122, in sql
    self.connect()
  File "/home/attiq/frappe-bench/apps/frappe/frappe/database/database.py", line 75, in connect
    self._conn = self.get_connection()
  File "/home/attiq/frappe-bench/apps/frappe/frappe/database/mariadb/database.py", line 90, in get_connection
    local_infile = frappe.conf.local_infile)
  File "/home/attiq/frappe-bench/env/lib/python3.6/site-packages/pymysql/__init__.py", line 94, in Connect
    return Connection(*args, **kwargs)
  File "/home/attiq/frappe-bench/env/lib/python3.6/site-packages/pymysql/connections.py", line 325, in __init__
    self.connect()
  File "/home/attiq/frappe-bench/env/lib/python3.6/site-packages/pymysql/connections.py", line 630, in connect
    raise exc
pymysql.err.OperationalError: (2003, "Can't connect to MySQL server on '192.168.2.219' (timed out)")

[ERROR] 2021-11-30 11:34:48,484 | /home/attiq/frappe-bench/apps/frappe/frappe/utils/scheduler.py:
Site: local.nerp
Exception in Enqueue Events for Site local.nerp
Traceback (most recent call last):
  File "/home/attiq/frappe-bench/env/lib/python3.6/site-packages/pymysql/connections.py", line 583, in connect
    **kwargs)
  File "/usr/lib/python3.6/socket.py", line 724, in create_connection
    raise err
  File "/usr/lib/python3.6/socket.py", line 713, in create_connection
    sock.connect(sa)
socket.timeout: timed out

During handling of the above exception, another exception occurred:

Traceback (most recent call last):
  File "/home/attiq/frappe-bench/apps/frappe/frappe/utils/scheduler.py", line 81, in enqueue_events_for_site
    if is_scheduler_inactive():
  File "/home/attiq/frappe-bench/apps/frappe/frappe/utils/scheduler.py", line 228, in is_scheduler_inactive
    if is_scheduler_disabled():
  File "/home/attiq/frappe-bench/apps/frappe/frappe/utils/scheduler.py", line 237, in is_scheduler_disabled
    return not frappe.utils.cint(frappe.db.get_single_value("System Settings", "enable_scheduler"))
  File "/home/attiq/frappe-bench/apps/frappe/frappe/database/database.py", line 553, in get_single_value
    `tabSingles` where `doctype`=%s and `field`=%s""", (doctype, fieldname))
  File "/home/attiq/frappe-bench/apps/frappe/frappe/database/database.py", line 122, in sql
    self.connect()
  File "/home/attiq/frappe-bench/apps/frappe/frappe/database/database.py", line 75, in connect
    self._conn = self.get_connection()
  File "/home/attiq/frappe-bench/apps/frappe/frappe/database/mariadb/database.py", line 90, in get_connection
    local_infile = frappe.conf.local_infile)
  File "/home/attiq/frappe-bench/env/lib/python3.6/site-packages/pymysql/__init__.py", line 94, in Connect
    return Connection(*args, **kwargs)
  File "/home/attiq/frappe-bench/env/lib/python3.6/site-packages/pymysql/connections.py", line 325, in __init__
    self.connect()
  File "/home/attiq/frappe-bench/env/lib/python3.6/site-packages/pymysql/connections.py", line 630, in connect
    raise exc
pymysql.err.OperationalError: (2003, "Can't connect to MySQL server on '192.168.2.219' (timed out)")

