[ERROR] 2021-11-17 16:21:57,045 | /home/attiq/frappe-sugarmill/apps/frappe/frappe/app.py:
Site: gourmet.sugarmill
Request Error
Traceback (most recent call last):
  File "/home/attiq/frappe-sugarmill/env/lib/python3.6/site-packages/pymysql/connections.py", line 583, in connect
    **kwargs)
  File "/usr/lib/python3.6/socket.py", line 724, in create_connection
    raise err
  File "/usr/lib/python3.6/socket.py", line 713, in create_connection
    sock.connect(sa)
socket.timeout: timed out

During handling of the above exception, another exception occurred:

Traceback (most recent call last):
  File "/home/attiq/frappe-sugarmill/apps/frappe/frappe/app.py", line 54, in application
    init_request(request)
  File "/home/attiq/frappe-sugarmill/apps/frappe/frappe/app.py", line 125, in init_request
    frappe.local.http_request = frappe.auth.HTTPRequest()
  File "/home/attiq/frappe-sugarmill/apps/frappe/frappe/auth.py", line 51, in __init__
    frappe.local.login_manager = LoginManager()
  File "/home/attiq/frappe-sugarmill/apps/frappe/frappe/auth.py", line 114, in __init__
    self.get_user_info()
  File "/home/attiq/frappe-sugarmill/apps/frappe/frappe/auth.py", line 149, in get_user_info
    ["user_type", "first_name", "last_name", "user_image"], as_dict=1)
  File "/home/attiq/frappe-sugarmill/apps/frappe/frappe/database/database.py", line 401, in get_value
    order_by, cache=cache)
  File "/home/attiq/frappe-sugarmill/apps/frappe/frappe/database/database.py", line 445, in get_values
    out = self._get_values_from_table(fields, filters, doctype, as_dict, debug, order_by, update)
  File "/home/attiq/frappe-sugarmill/apps/frappe/frappe/database/database.py", line 592, in _get_values_from_table
    as_dict=as_dict, debug=debug, update=update)
  File "/home/attiq/frappe-sugarmill/apps/frappe/frappe/database/database.py", line 122, in sql
    self.connect()
  File "/home/attiq/frappe-sugarmill/apps/frappe/frappe/database/database.py", line 75, in connect
    self._conn = self.get_connection()
  File "/home/attiq/frappe-sugarmill/apps/frappe/frappe/database/mariadb/database.py", line 90, in get_connection
    local_infile = frappe.conf.local_infile)
  File "/home/attiq/frappe-sugarmill/env/lib/python3.6/site-packages/pymysql/__init__.py", line 94, in Connect
    return Connection(*args, **kwargs)
  File "/home/attiq/frappe-sugarmill/env/lib/python3.6/site-packages/pymysql/connections.py", line 325, in __init__
    self.connect()
  File "/home/attiq/frappe-sugarmill/env/lib/python3.6/site-packages/pymysql/connections.py", line 630, in connect
    raise exc
pymysql.err.OperationalError: (2003, "Can't connect to MySQL server on '192.168.2.116' (timed out)")
