[ERROR] 2021-11-17 16:21:57,045 | /home/attiq/frappe-sugarmill/apps/frappe/frappe/app.py:
Site: gourmet.sugarmill
Site: gourmet.sugarmill
Request Error
Traceback (most recent call last):
  File "/home/attiq/frappe-sugarmill/env/lib/python3.6/site-packages/pymysql/connections.py", line 583, in connect
    **kwargs)
  File "/usr/lib/python3.6/socket.py", line 724, in create_connection
    raise err
  File "/usr/lib/python3.6/socket.py", line 713, in create_connection
    sock.connect(sa)
socket.timeout: timed out

During handling of the above exception, another exception occurred:

Traceback (most recent call last):
  File "/home/attiq/frappe-sugarmill/apps/frappe/frappe/app.py", line 54, in application
    init_request(request)
  File "/home/attiq/frappe-sugarmill/apps/frappe/frappe/app.py", line 125, in init_request
    frappe.local.http_request = frappe.auth.HTTPRequest()
  File "/home/attiq/frappe-sugarmill/apps/frappe/frappe/auth.py", line 51, in __init__
    frappe.local.login_manager = LoginManager()
  File "/home/attiq/frappe-sugarmill/apps/frappe/frappe/auth.py", line 114, in __init__
    self.get_user_info()
  File "/home/attiq/frappe-sugarmill/apps/frappe/frappe/auth.py", line 149, in get_user_info
    ["user_type", "first_name", "last_name", "user_image"], as_dict=1)
  File "/home/attiq/frappe-sugarmill/apps/frappe/frappe/database/database.py", line 401, in get_value
    order_by, cache=cache)
  File "/home/attiq/frappe-sugarmill/apps/frappe/frappe/database/database.py", line 445, in get_values
    out = self._get_values_from_table(fields, filters, doctype, as_dict, debug, order_by, update)
  File "/home/attiq/frappe-sugarmill/apps/frappe/frappe/database/database.py", line 592, in _get_values_from_table
    as_dict=as_dict, debug=debug, update=update)
  File "/home/attiq/frappe-sugarmill/apps/frappe/frappe/database/database.py", line 122, in sql
    self.connect()
  File "/home/attiq/frappe-sugarmill/apps/frappe/frappe/database/database.py", line 75, in connect
    self._conn = self.get_connection()
  File "/home/attiq/frappe-sugarmill/apps/frappe/frappe/database/mariadb/database.py", line 90, in get_connection
    local_infile = frappe.conf.local_infile)
  File "/home/attiq/frappe-sugarmill/env/lib/python3.6/site-packages/pymysql/__init__.py", line 94, in Connect
    return Connection(*args, **kwargs)
  File "/home/attiq/frappe-sugarmill/env/lib/python3.6/site-packages/pymysql/connections.py", line 325, in __init__
    self.connect()
  File "/home/attiq/frappe-sugarmill/env/lib/python3.6/site-packages/pymysql/connections.py", line 630, in connect
    raise exc
pymysql.err.OperationalError: (2003, "Can't connect to MySQL server on '192.168.2.116' (timed out)")
[ERROR] 2021-11-17 19:20:45,140 | /home/attiq/frappe-sugarmill/apps/frappe/frappe/app.py:
Site: gourmet.sugarmill
Request Error
Traceback (most recent call last):
  File "/home/attiq/frappe-sugarmill/env/lib/python3.6/site-packages/pymysql/connections.py", line 583, in connect
    **kwargs)
  File "/usr/lib/python3.6/socket.py", line 724, in create_connection
    raise err
  File "/usr/lib/python3.6/socket.py", line 713, in create_connection
    sock.connect(sa)
OSError: [Errno 113] No route to host

During handling of the above exception, another exception occurred:

Traceback (most recent call last):
  File "/home/attiq/frappe-sugarmill/apps/frappe/frappe/app.py", line 54, in application
    init_request(request)
  File "/home/attiq/frappe-sugarmill/apps/frappe/frappe/app.py", line 125, in init_request
    frappe.local.http_request = frappe.auth.HTTPRequest()
  File "/home/attiq/frappe-sugarmill/apps/frappe/frappe/auth.py", line 51, in __init__
    frappe.local.login_manager = LoginManager()
  File "/home/attiq/frappe-sugarmill/apps/frappe/frappe/auth.py", line 114, in __init__
    self.get_user_info()
  File "/home/attiq/frappe-sugarmill/apps/frappe/frappe/auth.py", line 149, in get_user_info
    ["user_type", "first_name", "last_name", "user_image"], as_dict=1)
  File "/home/attiq/frappe-sugarmill/apps/frappe/frappe/database/database.py", line 401, in get_value
    order_by, cache=cache)
  File "/home/attiq/frappe-sugarmill/apps/frappe/frappe/database/database.py", line 445, in get_values
    out = self._get_values_from_table(fields, filters, doctype, as_dict, debug, order_by, update)
  File "/home/attiq/frappe-sugarmill/apps/frappe/frappe/database/database.py", line 592, in _get_values_from_table
    as_dict=as_dict, debug=debug, update=update)
  File "/home/attiq/frappe-sugarmill/apps/frappe/frappe/database/database.py", line 122, in sql
    self.connect()
  File "/home/attiq/frappe-sugarmill/apps/frappe/frappe/database/database.py", line 75, in connect
    self._conn = self.get_connection()
  File "/home/attiq/frappe-sugarmill/apps/frappe/frappe/database/mariadb/database.py", line 90, in get_connection
    local_infile = frappe.conf.local_infile)
  File "/home/attiq/frappe-sugarmill/env/lib/python3.6/site-packages/pymysql/__init__.py", line 94, in Connect
    return Connection(*args, **kwargs)
  File "/home/attiq/frappe-sugarmill/env/lib/python3.6/site-packages/pymysql/connections.py", line 325, in __init__
    self.connect()
  File "/home/attiq/frappe-sugarmill/env/lib/python3.6/site-packages/pymysql/connections.py", line 630, in connect
    raise exc
pymysql.err.OperationalError: (2003, "Can't connect to MySQL server on '192.168.2.116' ([Errno 113] No route to host)")
[ERROR] 2021-11-17 19:20:45,194 | /home/attiq/frappe-sugarmill/apps/frappe/frappe/utils/error.py:
New Exception collected with id: 2021-11-17 19:20:45.141204-127.0.0.1-c4d
[ERROR] 2021-11-18 11:01:39,846 | /home/attiq/frappe-sugarmill/apps/frappe/frappe/app.py:
Site: gourmet.sugarmill
Request Error
Traceback (most recent call last):
  File "/home/attiq/frappe-sugarmill/env/lib/python3.6/site-packages/pymysql/connections.py", line 583, in connect
    **kwargs)
  File "/usr/lib/python3.6/socket.py", line 724, in create_connection
    raise err
  File "/usr/lib/python3.6/socket.py", line 713, in create_connection
    sock.connect(sa)
OSError: [Errno 101] Network is unreachable

During handling of the above exception, another exception occurred:

Traceback (most recent call last):
  File "/home/attiq/frappe-sugarmill/apps/frappe/frappe/app.py", line 54, in application
    init_request(request)
  File "/home/attiq/frappe-sugarmill/apps/frappe/frappe/app.py", line 125, in init_request
    frappe.local.http_request = frappe.auth.HTTPRequest()
  File "/home/attiq/frappe-sugarmill/apps/frappe/frappe/auth.py", line 51, in __init__
    frappe.local.login_manager = LoginManager()
  File "/home/attiq/frappe-sugarmill/apps/frappe/frappe/auth.py", line 113, in __init__
    self.make_session(resume=True)
  File "/home/attiq/frappe-sugarmill/apps/frappe/frappe/auth.py", line 188, in make_session
    full_name=self.full_name, user_type=self.user_type)
  File "/home/attiq/frappe-sugarmill/apps/frappe/frappe/sessions.py", line 194, in __init__
    self.resume()
  File "/home/attiq/frappe-sugarmill/apps/frappe/frappe/sessions.py", line 255, in resume
    data = self.get_session_record()
  File "/home/attiq/frappe-sugarmill/apps/frappe/frappe/sessions.py", line 273, in get_session_record
    r = self.get_session_data()
  File "/home/attiq/frappe-sugarmill/apps/frappe/frappe/sessions.py", line 287, in get_session_data
    data = self.get_session_data_from_cache()
  File "/home/attiq/frappe-sugarmill/apps/frappe/frappe/sessions.py", line 305, in get_session_data_from_cache
    self.delete_session()
  File "/home/attiq/frappe-sugarmill/apps/frappe/frappe/sessions.py", line 330, in delete_session
    delete_session(self.sid, reason="Session Expired")
  File "/home/attiq/frappe-sugarmill/apps/frappe/frappe/sessions.py", line 84, in delete_session
    user_details = frappe.db.sql("""select user from tabSessions where sid=%s""", sid, as_dict=True)
  File "/home/attiq/frappe-sugarmill/apps/frappe/frappe/database/database.py", line 122, in sql
    self.connect()
  File "/home/attiq/frappe-sugarmill/apps/frappe/frappe/database/database.py", line 75, in connect
    self._conn = self.get_connection()
  File "/home/attiq/frappe-sugarmill/apps/frappe/frappe/database/mariadb/database.py", line 90, in get_connection
    local_infile = frappe.conf.local_infile)
  File "/home/attiq/frappe-sugarmill/env/lib/python3.6/site-packages/pymysql/__init__.py", line 94, in Connect
    return Connection(*args, **kwargs)
  File "/home/attiq/frappe-sugarmill/env/lib/python3.6/site-packages/pymysql/connections.py", line 325, in __init__
    self.connect()
  File "/home/attiq/frappe-sugarmill/env/lib/python3.6/site-packages/pymysql/connections.py", line 630, in connect
    raise exc
pymysql.err.OperationalError: (2003, "Can't connect to MySQL server on '192.168.2.116' ([Errno 101] Network is unreachable)")
[ERROR] 2021-11-18 11:01:39,850 | /home/attiq/frappe-sugarmill/apps/frappe/frappe/utils/error.py:
New Exception collected with id: 2021-11-18 11:01:39.846625-127.0.0.1-eb4
[ERROR] 2021-11-18 11:01:44,851 | /home/attiq/frappe-sugarmill/apps/frappe/frappe/app.py:
Site: gourmet.sugarmill
Request Error
Traceback (most recent call last):
  File "/home/attiq/frappe-sugarmill/env/lib/python3.6/site-packages/pymysql/connections.py", line 583, in connect
    **kwargs)
  File "/usr/lib/python3.6/socket.py", line 724, in create_connection
    raise err
  File "/usr/lib/python3.6/socket.py", line 713, in create_connection
    sock.connect(sa)
OSError: [Errno 101] Network is unreachable

During handling of the above exception, another exception occurred:

Traceback (most recent call last):
  File "/home/attiq/frappe-sugarmill/apps/frappe/frappe/app.py", line 54, in application
    init_request(request)
  File "/home/attiq/frappe-sugarmill/apps/frappe/frappe/app.py", line 125, in init_request
    frappe.local.http_request = frappe.auth.HTTPRequest()
  File "/home/attiq/frappe-sugarmill/apps/frappe/frappe/auth.py", line 51, in __init__
    frappe.local.login_manager = LoginManager()
  File "/home/attiq/frappe-sugarmill/apps/frappe/frappe/auth.py", line 113, in __init__
    self.make_session(resume=True)
  File "/home/attiq/frappe-sugarmill/apps/frappe/frappe/auth.py", line 188, in make_session
    full_name=self.full_name, user_type=self.user_type)
  File "/home/attiq/frappe-sugarmill/apps/frappe/frappe/sessions.py", line 194, in __init__
    self.resume()
  File "/home/attiq/frappe-sugarmill/apps/frappe/frappe/sessions.py", line 255, in resume
    data = self.get_session_record()
  File "/home/attiq/frappe-sugarmill/apps/frappe/frappe/sessions.py", line 273, in get_session_record
    r = self.get_session_data()
  File "/home/attiq/frappe-sugarmill/apps/frappe/frappe/sessions.py", line 289, in get_session_data
    data = self.get_session_data_from_db()
  File "/home/attiq/frappe-sugarmill/apps/frappe/frappe/sessions.py", line 311, in get_session_data_from_db
    self.device = frappe.db.sql('SELECT `device` FROM `tabSessions` WHERE `sid`=%s', self.sid)
  File "/home/attiq/frappe-sugarmill/apps/frappe/frappe/database/database.py", line 122, in sql
    self.connect()
  File "/home/attiq/frappe-sugarmill/apps/frappe/frappe/database/database.py", line 75, in connect
    self._conn = self.get_connection()
  File "/home/attiq/frappe-sugarmill/apps/frappe/frappe/database/mariadb/database.py", line 90, in get_connection
    local_infile = frappe.conf.local_infile)
  File "/home/attiq/frappe-sugarmill/env/lib/python3.6/site-packages/pymysql/__init__.py", line 94, in Connect
    return Connection(*args, **kwargs)
  File "/home/attiq/frappe-sugarmill/env/lib/python3.6/site-packages/pymysql/connections.py", line 325, in __init__
    self.connect()
  File "/home/attiq/frappe-sugarmill/env/lib/python3.6/site-packages/pymysql/connections.py", line 630, in connect
    raise exc
pymysql.err.OperationalError: (2003, "Can't connect to MySQL server on '192.168.2.116' ([Errno 101] Network is unreachable)")
[ERROR] 2021-11-18 11:01:44,857 | /home/attiq/frappe-sugarmill/apps/frappe/frappe/utils/error.py:
New Exception collected with id: 2021-11-18 11:01:44.852306-127.0.0.1-ecf
[ERROR] 2021-11-18 11:01:44,876 | /home/attiq/frappe-sugarmill/apps/frappe/frappe/app.py:
Site: gourmet.sugarmill
Request Error
Traceback (most recent call last):
  File "/home/attiq/frappe-sugarmill/env/lib/python3.6/site-packages/pymysql/connections.py", line 583, in connect
    **kwargs)
  File "/usr/lib/python3.6/socket.py", line 724, in create_connection
    raise err
  File "/usr/lib/python3.6/socket.py", line 713, in create_connection
    sock.connect(sa)
socket.timeout: timed out

During handling of the above exception, another exception occurred:

Traceback (most recent call last):
  File "/home/attiq/frappe-sugarmill/apps/frappe/frappe/app.py", line 54, in application
    init_request(request)
  File "/home/attiq/frappe-sugarmill/apps/frappe/frappe/app.py", line 125, in init_request
    frappe.local.http_request = frappe.auth.HTTPRequest()
  File "/home/attiq/frappe-sugarmill/apps/frappe/frappe/auth.py", line 51, in __init__
    frappe.local.login_manager = LoginManager()
  File "/home/attiq/frappe-sugarmill/apps/frappe/frappe/auth.py", line 114, in __init__
    self.get_user_info()
  File "/home/attiq/frappe-sugarmill/apps/frappe/frappe/auth.py", line 149, in get_user_info
    ["user_type", "first_name", "last_name", "user_image"], as_dict=1)
  File "/home/attiq/frappe-sugarmill/apps/frappe/frappe/database/database.py", line 401, in get_value
    order_by, cache=cache)
  File "/home/attiq/frappe-sugarmill/apps/frappe/frappe/database/database.py", line 445, in get_values
    out = self._get_values_from_table(fields, filters, doctype, as_dict, debug, order_by, update)
  File "/home/attiq/frappe-sugarmill/apps/frappe/frappe/database/database.py", line 592, in _get_values_from_table
    as_dict=as_dict, debug=debug, update=update)
  File "/home/attiq/frappe-sugarmill/apps/frappe/frappe/database/database.py", line 122, in sql
    self.connect()
  File "/home/attiq/frappe-sugarmill/apps/frappe/frappe/database/database.py", line 75, in connect
    self._conn = self.get_connection()
  File "/home/attiq/frappe-sugarmill/apps/frappe/frappe/database/mariadb/database.py", line 90, in get_connection
    local_infile = frappe.conf.local_infile)
  File "/home/attiq/frappe-sugarmill/env/lib/python3.6/site-packages/pymysql/__init__.py", line 94, in Connect
    return Connection(*args, **kwargs)
  File "/home/attiq/frappe-sugarmill/env/lib/python3.6/site-packages/pymysql/connections.py", line 325, in __init__
    self.connect()
  File "/home/attiq/frappe-sugarmill/env/lib/python3.6/site-packages/pymysql/connections.py", line 630, in connect
    raise exc
pymysql.err.OperationalError: (2003, "Can't connect to MySQL server on '192.168.2.116' (timed out)")
[ERROR] 2021-11-18 11:01:44,881 | /home/attiq/frappe-sugarmill/apps/frappe/frappe/utils/error.py:
New Exception collected with id: 2021-11-18 11:01:44.877337-127.0.0.1-c83
[ERROR] 2021-11-18 11:01:49,849 | /home/attiq/frappe-sugarmill/apps/frappe/frappe/app.py:
Site: gourmet.sugarmill
Request Error
Traceback (most recent call last):
  File "/home/attiq/frappe-sugarmill/env/lib/python3.6/site-packages/pymysql/connections.py", line 583, in connect
    **kwargs)
  File "/usr/lib/python3.6/socket.py", line 724, in create_connection
    raise err
  File "/usr/lib/python3.6/socket.py", line 713, in create_connection
    sock.connect(sa)
OSError: [Errno 101] Network is unreachable

During handling of the above exception, another exception occurred:

Traceback (most recent call last):
  File "/home/attiq/frappe-sugarmill/apps/frappe/frappe/app.py", line 54, in application
    init_request(request)
  File "/home/attiq/frappe-sugarmill/apps/frappe/frappe/app.py", line 125, in init_request
    frappe.local.http_request = frappe.auth.HTTPRequest()
  File "/home/attiq/frappe-sugarmill/apps/frappe/frappe/auth.py", line 51, in __init__
    frappe.local.login_manager = LoginManager()
  File "/home/attiq/frappe-sugarmill/apps/frappe/frappe/auth.py", line 113, in __init__
    self.make_session(resume=True)
  File "/home/attiq/frappe-sugarmill/apps/frappe/frappe/auth.py", line 188, in make_session
    full_name=self.full_name, user_type=self.user_type)
  File "/home/attiq/frappe-sugarmill/apps/frappe/frappe/sessions.py", line 194, in __init__
    self.resume()
  File "/home/attiq/frappe-sugarmill/apps/frappe/frappe/sessions.py", line 255, in resume
    data = self.get_session_record()
  File "/home/attiq/frappe-sugarmill/apps/frappe/frappe/sessions.py", line 273, in get_session_record
    r = self.get_session_data()
  File "/home/attiq/frappe-sugarmill/apps/frappe/frappe/sessions.py", line 289, in get_session_data
    data = self.get_session_data_from_db()
  File "/home/attiq/frappe-sugarmill/apps/frappe/frappe/sessions.py", line 311, in get_session_data_from_db
    self.device = frappe.db.sql('SELECT `device` FROM `tabSessions` WHERE `sid`=%s', self.sid)
  File "/home/attiq/frappe-sugarmill/apps/frappe/frappe/database/database.py", line 122, in sql
    self.connect()
  File "/home/attiq/frappe-sugarmill/apps/frappe/frappe/database/database.py", line 75, in connect
    self._conn = self.get_connection()
  File "/home/attiq/frappe-sugarmill/apps/frappe/frappe/database/mariadb/database.py", line 90, in get_connection
    local_infile = frappe.conf.local_infile)
  File "/home/attiq/frappe-sugarmill/env/lib/python3.6/site-packages/pymysql/__init__.py", line 94, in Connect
    return Connection(*args, **kwargs)
  File "/home/attiq/frappe-sugarmill/env/lib/python3.6/site-packages/pymysql/connections.py", line 325, in __init__
    self.connect()
  File "/home/attiq/frappe-sugarmill/env/lib/python3.6/site-packages/pymysql/connections.py", line 630, in connect
    raise exc
pymysql.err.OperationalError: (2003, "Can't connect to MySQL server on '192.168.2.116' ([Errno 101] Network is unreachable)")
[ERROR] 2021-11-18 11:01:49,857 | /home/attiq/frappe-sugarmill/apps/frappe/frappe/utils/error.py:
New Exception collected with id: 2021-11-18 11:01:49.850595-127.0.0.1-69a
[ERROR] 2021-11-18 11:01:54,850 | /home/attiq/frappe-sugarmill/apps/frappe/frappe/app.py:
Site: gourmet.sugarmill
Request Error
Traceback (most recent call last):
  File "/home/attiq/frappe-sugarmill/env/lib/python3.6/site-packages/pymysql/connections.py", line 583, in connect
    **kwargs)
  File "/usr/lib/python3.6/socket.py", line 724, in create_connection
    raise err
  File "/usr/lib/python3.6/socket.py", line 713, in create_connection
    sock.connect(sa)
OSError: [Errno 101] Network is unreachable

During handling of the above exception, another exception occurred:

Traceback (most recent call last):
  File "/home/attiq/frappe-sugarmill/apps/frappe/frappe/app.py", line 54, in application
    init_request(request)
  File "/home/attiq/frappe-sugarmill/apps/frappe/frappe/app.py", line 125, in init_request
    frappe.local.http_request = frappe.auth.HTTPRequest()
  File "/home/attiq/frappe-sugarmill/apps/frappe/frappe/auth.py", line 51, in __init__
    frappe.local.login_manager = LoginManager()
  File "/home/attiq/frappe-sugarmill/apps/frappe/frappe/auth.py", line 113, in __init__
    self.make_session(resume=True)
  File "/home/attiq/frappe-sugarmill/apps/frappe/frappe/auth.py", line 188, in make_session
    full_name=self.full_name, user_type=self.user_type)
  File "/home/attiq/frappe-sugarmill/apps/frappe/frappe/sessions.py", line 194, in __init__
    self.resume()
  File "/home/attiq/frappe-sugarmill/apps/frappe/frappe/sessions.py", line 255, in resume
    data = self.get_session_record()
  File "/home/attiq/frappe-sugarmill/apps/frappe/frappe/sessions.py", line 273, in get_session_record
    r = self.get_session_data()
  File "/home/attiq/frappe-sugarmill/apps/frappe/frappe/sessions.py", line 289, in get_session_data
    data = self.get_session_data_from_db()
  File "/home/attiq/frappe-sugarmill/apps/frappe/frappe/sessions.py", line 311, in get_session_data_from_db
    self.device = frappe.db.sql('SELECT `device` FROM `tabSessions` WHERE `sid`=%s', self.sid)
  File "/home/attiq/frappe-sugarmill/apps/frappe/frappe/database/database.py", line 122, in sql
    self.connect()
  File "/home/attiq/frappe-sugarmill/apps/frappe/frappe/database/database.py", line 75, in connect
    self._conn = self.get_connection()
  File "/home/attiq/frappe-sugarmill/apps/frappe/frappe/database/mariadb/database.py", line 90, in get_connection
    local_infile = frappe.conf.local_infile)
  File "/home/attiq/frappe-sugarmill/env/lib/python3.6/site-packages/pymysql/__init__.py", line 94, in Connect
    return Connection(*args, **kwargs)
  File "/home/attiq/frappe-sugarmill/env/lib/python3.6/site-packages/pymysql/connections.py", line 325, in __init__
    self.connect()
  File "/home/attiq/frappe-sugarmill/env/lib/python3.6/site-packages/pymysql/connections.py", line 630, in connect
    raise exc
pymysql.err.OperationalError: (2003, "Can't connect to MySQL server on '192.168.2.116' ([Errno 101] Network is unreachable)")
[ERROR] 2021-11-18 11:01:54,857 | /home/attiq/frappe-sugarmill/apps/frappe/frappe/utils/error.py:
New Exception collected with id: 2021-11-18 11:01:54.851281-127.0.0.1-a02
[ERROR] 2021-11-18 11:01:58,140 | /home/attiq/frappe-sugarmill/apps/frappe/frappe/app.py:
Site: gourmet.sugarmill
Request Error
Traceback (most recent call last):
  File "/home/attiq/frappe-sugarmill/env/lib/python3.6/site-packages/pymysql/connections.py", line 583, in connect
    **kwargs)
  File "/usr/lib/python3.6/socket.py", line 724, in create_connection
    raise err
  File "/usr/lib/python3.6/socket.py", line 713, in create_connection
    sock.connect(sa)
OSError: [Errno 101] Network is unreachable

During handling of the above exception, another exception occurred:

Traceback (most recent call last):
  File "/home/attiq/frappe-sugarmill/apps/frappe/frappe/app.py", line 54, in application
    init_request(request)
  File "/home/attiq/frappe-sugarmill/apps/frappe/frappe/app.py", line 125, in init_request
    frappe.local.http_request = frappe.auth.HTTPRequest()
  File "/home/attiq/frappe-sugarmill/apps/frappe/frappe/auth.py", line 51, in __init__
    frappe.local.login_manager = LoginManager()
  File "/home/attiq/frappe-sugarmill/apps/frappe/frappe/auth.py", line 113, in __init__
    self.make_session(resume=True)
  File "/home/attiq/frappe-sugarmill/apps/frappe/frappe/auth.py", line 188, in make_session
    full_name=self.full_name, user_type=self.user_type)
  File "/home/attiq/frappe-sugarmill/apps/frappe/frappe/sessions.py", line 194, in __init__
    self.resume()
  File "/home/attiq/frappe-sugarmill/apps/frappe/frappe/sessions.py", line 255, in resume
    data = self.get_session_record()
  File "/home/attiq/frappe-sugarmill/apps/frappe/frappe/sessions.py", line 273, in get_session_record
    r = self.get_session_data()
  File "/home/attiq/frappe-sugarmill/apps/frappe/frappe/sessions.py", line 289, in get_session_data
    data = self.get_session_data_from_db()
  File "/home/attiq/frappe-sugarmill/apps/frappe/frappe/sessions.py", line 311, in get_session_data_from_db
    self.device = frappe.db.sql('SELECT `device` FROM `tabSessions` WHERE `sid`=%s', self.sid)
  File "/home/attiq/frappe-sugarmill/apps/frappe/frappe/database/database.py", line 122, in sql
    self.connect()
  File "/home/attiq/frappe-sugarmill/apps/frappe/frappe/database/database.py", line 75, in connect
    self._conn = self.get_connection()
  File "/home/attiq/frappe-sugarmill/apps/frappe/frappe/database/mariadb/database.py", line 90, in get_connection
    local_infile = frappe.conf.local_infile)
  File "/home/attiq/frappe-sugarmill/env/lib/python3.6/site-packages/pymysql/__init__.py", line 94, in Connect
    return Connection(*args, **kwargs)
  File "/home/attiq/frappe-sugarmill/env/lib/python3.6/site-packages/pymysql/connections.py", line 325, in __init__
    self.connect()
  File "/home/attiq/frappe-sugarmill/env/lib/python3.6/site-packages/pymysql/connections.py", line 630, in connect
    raise exc
pymysql.err.OperationalError: (2003, "Can't connect to MySQL server on '192.168.2.116' ([Errno 101] Network is unreachable)")
[ERROR] 2021-11-18 11:01:58,146 | /home/attiq/frappe-sugarmill/apps/frappe/frappe/utils/error.py:
New Exception collected with id: 2021-11-18 11:01:58.140803-127.0.0.1-0ee
